<?xml version="1.0"?>
<robot name="articulated_ant">

  <material name="Blue"> <!-- for spheres -->
    <color rgba="0 0 1 0.5"/>
  </material>
  <material name="White">
    <color rgba="1 1 1 1"/>
  </material>
  <material name="Gray">
    <color rgba="0.6 0.6 0.6 1"/>
  </material>
  <material name="Green">
    <color rgba="0 0.9 0 0.4"/>
  </material>

  <link name="base_link"/>
  <joint name="base_link_J" type="fixed">
      <parent link="base_link"/>
      <child link="Thorax"/>
      <origin rpy="0 0 1.570796" xyz="0 0 0"/>
   </joint>

  <link name="virtualThorax"/> <!-- for Blender Armature export -->
  <joint name="virtualThorax" type="fixed">
      <parent link="base_link"/>
      <child link="virtualThorax"/>
      <origin rpy="0 0 0" xyz="0 0 0"/>
  </joint>

  <link name="Thorax">
      <inertial>
         <origin rpy="0 0 0" xyz="0 0 0"/>
         <mass value="1"/>
         <inertia ixx="0" ixy="0" ixz="0" iyy="0" iyz="0" izz="0"/>
      </inertial>
      <visual>
         <origin xyz="0 0 0" rpy="0 0 0"/>
         <geometry>
            <mesh filename="package://hpp-rbprm-corba/meshes/ant/Thorax.stl"/>
         </geometry>
         <material name="Gray"/>
      </visual>
      <collision>
         <origin xyz="0 0 0" rpy="0 0 0"/>
         <geometry>
            <mesh filename="package://hpp-rbprm-corba/meshes/ant/Thorax.stl"/>
         </geometry>
      </collision>
   </link>

   <!--<joint name="thorax_foot_rom_joint" type="fixed">
      <parent link="Thorax"/>
      <child link="thorax_foot_rom"/>
      <origin rpy="0 0 0" xyz="0 0 0"/>
   </joint>

  <link name="thorax_foot_rom">
      <visual>
         <origin xyz="0 0 0" rpy="0 0 0"/>
         <geometry>
            <mesh filename="package://hpp-rbprm-corba/meshes/ant/rbfoot_rom.stl"/>
         </geometry>
         <material name="Green"/>
      </visual>
   </link>-->

   <link name="Abdomen_rx"/>
   <link name="Abdomen_ry"/>
   <link name="Abdomen">
      <inertial>
         <origin rpy="0 0 0" xyz="0 0 0"/>
         <mass value="0"/>
         <inertia ixx="0" ixy="0" ixz="0" iyy="0" iyz="0" izz="0"/>
      </inertial>
      <visual>
         <origin xyz="0 0 0" rpy="0 0 0"/>
         <geometry>
            <mesh filename="package://hpp-rbprm-corba/meshes/ant/Abdomen.stl"/>
         </geometry>
         <material name="Gray"/>
      </visual>
      <collision>
         <origin xyz="0 0 0" rpy="0 0 0"/>
         <geometry>
            <mesh filename="package://hpp-rbprm-corba/meshes/ant/Abdomen.stl"/>
         </geometry>
      </collision>
   </link>
   <link name="Head_rx"/>
   <link name="Head_ry"/>
   <link name="Head">
      <inertial>
         <origin rpy="0 0 0" xyz="0 0 0"/>
         <mass value="4.2276"/>
         <inertia ixx="0.0071027" ixy="-0.00059867" ixz="-2.9564e-05" iyy="0.0046194" iyz="6.6519e-05" izz="0.0080488"/>
      </inertial>
      <visual>
         <origin xyz="0 0 0" rpy="0 0 0"/>
         <geometry>
            <mesh filename="package://hpp-rbprm-corba/meshes/ant/Skull.stl"/>
         </geometry>
         <material name="Gray"/>
      </visual>
      <collision>
         <origin xyz="0 0 0" rpy="0 0 0"/>
         <geometry>
            <mesh filename="package://hpp-rbprm-corba/meshes/ant/Skull.stl"/>
         </geometry>
      </collision>
   </link>

   <link name="LAntena">
      <inertial>
         <origin rpy="0 0 0" xyz="0 0 0"/>
         <mass value="1"/>
         <inertia ixx="0.0071027" ixy="-0.00059867" ixz="-2.9564e-05" iyy="0.0046194" iyz="6.6519e-05" izz="0.0080488"/>
      </inertial>
      <visual>
         <origin xyz="0 0 0" rpy="0 0 0"/>
         <geometry>
            <mesh filename="package://hpp-rbprm-corba/meshes/ant/LAntena.stl"/>
         </geometry>
         <material name="Gray"/>
      </visual>
      <collision>
         <origin xyz="0 0 0" rpy="0 0 0"/>
         <geometry>
            <mesh filename="package://hpp-rbprm-corba/meshes/ant/LAntena.stl"/>
         </geometry>
      </collision>
   </link>

   <link name="LAntenaFoot">
      <inertial>
         <origin rpy="0 0 0" xyz="0 0 0"/>
         <mass value="1"/>
         <inertia ixx="0.0071027" ixy="-0.00059867" ixz="-2.9564e-05" iyy="0.0046194" iyz="6.6519e-05" izz="0.0080488"/>
      </inertial>
      <visual>
         <origin xyz="0 0 0" rpy="0 0 0"/>
         <geometry>
            <mesh filename="package://hpp-rbprm-corba/meshes/ant/LAntenaFoot.stl"/>
         </geometry>
         <material name="Gray"/>
      </visual>
      <collision>
         <origin xyz="0 0 0" rpy="0 0 0"/>
         <geometry>
            <mesh filename="package://hpp-rbprm-corba/meshes/ant/LAntenaFoot.stl"/>
         </geometry>
      </collision>
   </link>
   
   <link name="RAntena">
      <inertial>
         <origin rpy="0 0 0" xyz="0 0 0"/>
         <mass value="1"/>
         <inertia ixx="0.0071027" ixy="-0.00059867" ixz="-2.9564e-05" iyy="0.0046194" iyz="6.6519e-05" izz="0.0080488"/>
      </inertial>
      <visual>
         <origin xyz="0 0 0" rpy="0 0 0"/>
         <geometry>
            <mesh filename="package://hpp-rbprm-corba/meshes/ant/RAntena.stl"/>
         </geometry>
         <material name="Gray"/>
      </visual>
      <collision>
         <origin xyz="0 0 0" rpy="0 0 0"/>
         <geometry>
            <mesh filename="package://hpp-rbprm-corba/meshes/ant/RAntena.stl"/>
         </geometry>
      </collision>
   </link>

   <link name="RAntenaFoot">
      <inertial>
         <origin rpy="0 0 0" xyz="0 0 0"/>
         <mass value="1"/>
         <inertia ixx="0.0071027" ixy="-0.00059867" ixz="-2.9564e-05" iyy="0.0046194" iyz="6.6519e-05" izz="0.0080488"/>
      </inertial>
      <visual>
         <origin xyz="0 0 0" rpy="0 0 0"/>
         <geometry>
            <mesh filename="package://hpp-rbprm-corba/meshes/ant/RAntenaFoot.stl"/>
         </geometry>
         <material name="Gray"/>
      </visual>
      <collision>
         <origin xyz="0 0 0" rpy="0 0 0"/>
         <geometry>
            <mesh filename="package://hpp-rbprm-corba/meshes/ant/RAntenaFoot.stl"/>
         </geometry>
      </collision>
   </link>
   
   <!-- L = left, R = right, F = front, M = middle, B = back -->
   <link name="LFThigh_rx"/>
   <link name="LFThigh_ry"/>
   <link name="LFThigh">
      <inertial>
         <origin rpy="0 0 0" xyz="0 0 0"/>
         <mass value="1"/>
         <inertia ixx="0.0071027" ixy="-0.00059867" ixz="-2.9564e-05" iyy="0.0046194" iyz="6.6519e-05" izz="0.0080488"/>
      </inertial>
      <visual>
         <origin xyz="0 0 0" rpy="0 0 0"/>
         <geometry>
            <mesh filename="package://hpp-rbprm-corba/meshes/ant/LFThigh.stl"/>
         </geometry>
         <material name="Gray"/>
      </visual>
      <collision>
         <origin xyz="0 0 0" rpy="0 0 0"/>
         <geometry>
            <mesh filename="package://hpp-rbprm-corba/meshes/ant/LFThigh.stl"/>
         </geometry>
      </collision>
   </link>
   
   <link name="LFShank_rx"/>
   <link name="LFShank_ry"/>
   <link name="LFShank">
      <inertial>
         <origin rpy="0 0 0" xyz="0 0 0"/>
         <mass value="1"/>
         <inertia ixx="0.0071027" ixy="-0.00059867" ixz="-2.9564e-05" iyy="0.0046194" iyz="6.6519e-05" izz="0.0080488"/>
      </inertial>
      <visual>
         <origin xyz="0 0 0" rpy="0 0 0"/>
         <geometry>
            <mesh filename="package://hpp-rbprm-corba/meshes/ant/LFShank.stl"/>
         </geometry>
         <material name="Gray"/>
      </visual>
      <collision>
         <origin xyz="0 0 0" rpy="0 0 0"/>
         <geometry>
            <mesh filename="package://hpp-rbprm-corba/meshes/ant/LFShank.stl"/>
         </geometry>
      </collision>
   </link>
   
   <link name="LFFoot_rx"/>
   <link name="LFFoot_ry"/>
   <link name="LFFoot">
      <inertial>
         <origin rpy="0 0 0" xyz="0 0 0"/>
         <mass value="1"/>
         <inertia ixx="0.0071027" ixy="-0.00059867" ixz="-2.9564e-05" iyy="0.0046194" iyz="6.6519e-05" izz="0.0080488"/>
      </inertial>
      <visual>
         <origin xyz="0 0 0" rpy="0 0 0"/>
         <geometry>
            <mesh filename="package://hpp-rbprm-corba/meshes/ant/LFFoot.stl"/>
         </geometry>
         <material name="Gray"/>
      </visual>
      <collision>
         <origin xyz="0 0 0" rpy="0 0 0"/>
         <geometry>
            <mesh filename="package://hpp-rbprm-corba/meshes/ant/LFFoot.stl"/>
         </geometry>
      </collision>
   </link>
   
   <link name="LMThigh_rx"/>
   <link name="LMThigh_ry"/>
   <link name="LMThigh">
      <inertial>
         <origin rpy="0 0 0" xyz="0 0 0"/>
         <mass value="1"/>
         <inertia ixx="0.0071027" ixy="-0.00059867" ixz="-2.9564e-05" iyy="0.0046194" iyz="6.6519e-05" izz="0.0080488"/>
      </inertial>
      <visual>
         <origin xyz="0 0 0" rpy="0 0 0"/>
         <geometry>
            <mesh filename="package://hpp-rbprm-corba/meshes/ant/LMThigh.stl"/>
         </geometry>
         <material name="Gray"/>
      </visual>
      <collision>
         <origin xyz="0 0 0" rpy="0 0 0"/>
         <geometry>
            <mesh filename="package://hpp-rbprm-corba/meshes/ant/LMThigh.stl"/>
         </geometry>
      </collision>
   </link>
   
   <link name="LMShank_rx"/>
   <link name="LMShank_ry"/>
   <link name="LMShank">
      <inertial>
         <origin rpy="0 0 0" xyz="0 0 0"/>
         <mass value="1"/>
         <inertia ixx="0.0071027" ixy="-0.00059867" ixz="-2.9564e-05" iyy="0.0046194" iyz="6.6519e-05" izz="0.0080488"/>
      </inertial>
      <visual>
         <origin xyz="0 0 0" rpy="0 0 0"/>
         <geometry>
            <mesh filename="package://hpp-rbprm-corba/meshes/ant/LMShank.stl"/>
         </geometry>
         <material name="Gray"/>
      </visual>
      <collision>
         <origin xyz="0 0 0" rpy="0 0 0"/>
         <geometry>
            <mesh filename="package://hpp-rbprm-corba/meshes/ant/LMShank.stl"/>
         </geometry>
      </collision>
   </link>
   
   <link name="LMFoot_rx"/>
   <link name="LMFoot_ry"/>
   <link name="LMFoot">
      <inertial>
         <origin rpy="0 0 0" xyz="0 0 0"/>
         <mass value="1"/>
         <inertia ixx="0.0071027" ixy="-0.00059867" ixz="-2.9564e-05" iyy="0.0046194" iyz="6.6519e-05" izz="0.0080488"/>
      </inertial>
      <visual>
         <origin xyz="0 0 0" rpy="0 0 0"/>
         <geometry>
            <mesh filename="package://hpp-rbprm-corba/meshes/ant/LMFoot.stl"/>
         </geometry>
         <material name="Gray"/>
      </visual>
      <collision>
         <origin xyz="0 0 0" rpy="0 0 0"/>
         <geometry>
            <mesh filename="package://hpp-rbprm-corba/meshes/ant/LMFoot.stl"/>
         </geometry>
      </collision>
   </link>
   
   <link name="LBThigh_rx"/>
   <link name="LBThigh_ry"/>
   <link name="LBThigh">
      <inertial>
         <origin rpy="0 0 0" xyz="0 0 0"/>
         <mass value="1"/>
         <inertia ixx="0.0071027" ixy="-0.00059867" ixz="-2.9564e-05" iyy="0.0046194" iyz="6.6519e-05" izz="0.0080488"/>
      </inertial>
      <visual>
         <origin xyz="0 0 0" rpy="0 0 0"/>
         <geometry>
            <mesh filename="package://hpp-rbprm-corba/meshes/ant/LBThigh.stl"/>
         </geometry>
         <material name="Gray"/>
      </visual>
      <collision>
         <origin xyz="0 0 0" rpy="0 0 0"/>
         <geometry>
            <mesh filename="package://hpp-rbprm-corba/meshes/ant/LBThigh.stl"/>
         </geometry>
      </collision>
   </link>
   
   <link name="LBShank_rx"/>
   <link name="LBShank_ry"/>
   <link name="LBShank">
      <inertial>
         <origin rpy="0 0 0" xyz="0 0 0"/>
         <mass value="1"/>
         <inertia ixx="0.0071027" ixy="-0.00059867" ixz="-2.9564e-05" iyy="0.0046194" iyz="6.6519e-05" izz="0.0080488"/>
      </inertial>
      <visual>
         <origin xyz="0 0 0" rpy="0 0 0"/>
         <geometry>
            <mesh filename="package://hpp-rbprm-corba/meshes/ant/LBShank.stl"/>
         </geometry>
         <material name="Gray"/>
      </visual>
      <collision>
         <origin xyz="0 0 0" rpy="0 0 0"/>
         <geometry>
            <mesh filename="package://hpp-rbprm-corba/meshes/ant/LBShank.stl"/>
         </geometry>
      </collision>
   </link>
   
   <link name="LBFoot_rx"/>
   <link name="LBFoot_ry"/>
   <link name="LBFoot">
      <inertial>
         <origin rpy="0 0 0" xyz="0 0 0"/>
         <mass value="1"/>
         <inertia ixx="0.0071027" ixy="-0.00059867" ixz="-2.9564e-05" iyy="0.0046194" iyz="6.6519e-05" izz="0.0080488"/>
      </inertial>
      <visual>
         <origin xyz="0 0 0" rpy="0 0 0"/>
         <geometry>
            <mesh filename="package://hpp-rbprm-corba/meshes/ant/LBFoot.stl"/>
         </geometry>
         <material name="Gray"/>
      </visual>
      <collision>
         <origin xyz="0 0 0" rpy="0 0 0"/>
         <geometry>
            <mesh filename="package://hpp-rbprm-corba/meshes/ant/LBFoot.stl"/>
         </geometry>
      </collision>
   </link>
   
      <link name="RFThigh_rx"/>
   <link name="RFThigh_ry"/>
   <link name="RFThigh">
      <inertial>
         <origin rpy="0 0 0" xyz="0 0 0"/>
         <mass value="1"/>
         <inertia ixx="0.0071027" ixy="-0.00059867" ixz="-2.9564e-05" iyy="0.0046194" iyz="6.6519e-05" izz="0.0080488"/>
      </inertial>
      <visual>
         <origin xyz="0 0 0" rpy="0 0 0"/>
         <geometry>
            <mesh filename="package://hpp-rbprm-corba/meshes/ant/RFThigh.stl"/>
         </geometry>
         <material name="Gray"/>
      </visual>
      <collision>
         <origin xyz="0 0 0" rpy="0 0 0"/>
         <geometry>
            <mesh filename="package://hpp-rbprm-corba/meshes/ant/RFThigh.stl"/>
         </geometry>
      </collision>
   </link>
   
   <link name="RFShank_rx"/>
   <link name="RFShank_ry"/>
   <link name="RFShank">
      <inertial>
         <origin rpy="0 0 0" xyz="0 0 0"/>
         <mass value="1"/>
         <inertia ixx="0.0071027" ixy="-0.00059867" ixz="-2.9564e-05" iyy="0.0046194" iyz="6.6519e-05" izz="0.0080488"/>
      </inertial>
      <visual>
         <origin xyz="0 0 0" rpy="0 0 0"/>
         <geometry>
            <mesh filename="package://hpp-rbprm-corba/meshes/ant/RFShank.stl"/>
         </geometry>
         <material name="Gray"/>
      </visual>
      <collision>
         <origin xyz="0 0 0" rpy="0 0 0"/>
         <geometry>
            <mesh filename="package://hpp-rbprm-corba/meshes/ant/RFShank.stl"/>
         </geometry>
      </collision>
   </link>
   
   <link name="RFFoot_rx"/>
   <link name="RFFoot_ry"/>
   <link name="RFFoot">
      <inertial>
         <origin rpy="0 0 0" xyz="0 0 0"/>
         <mass value="1"/>
         <inertia ixx="0.0071027" ixy="-0.00059867" ixz="-2.9564e-05" iyy="0.0046194" iyz="6.6519e-05" izz="0.0080488"/>
      </inertial>
      <visual>
         <origin xyz="0 0 0" rpy="0 0 0"/>
         <geometry>
            <mesh filename="package://hpp-rbprm-corba/meshes/ant/RFFoot.stl"/>
         </geometry>
         <material name="Gray"/>
      </visual>
      <collision>
         <origin xyz="0 0 0" rpy="0 0 0"/>
         <geometry>
            <mesh filename="package://hpp-rbprm-corba/meshes/ant/RFFoot.stl"/>
         </geometry>
      </collision>
   </link>
   
   <link name="RMThigh_rx"/>
   <link name="RMThigh_ry"/>
   <link name="RMThigh">
      <inertial>
         <origin rpy="0 0 0" xyz="0 0 0"/>
         <mass value="1"/>
         <inertia ixx="0.0071027" ixy="-0.00059867" ixz="-2.9564e-05" iyy="0.0046194" iyz="6.6519e-05" izz="0.0080488"/>
      </inertial>
      <visual>
         <origin xyz="0 0 0" rpy="0 0 0"/>
         <geometry>
            <mesh filename="package://hpp-rbprm-corba/meshes/ant/RMThigh.stl"/>
         </geometry>
         <material name="Gray"/>
      </visual>
      <collision>
         <origin xyz="0 0 0" rpy="0 0 0"/>
         <geometry>
            <mesh filename="package://hpp-rbprm-corba/meshes/ant/RMThigh.stl"/>
         </geometry>
      </collision>
   </link>
   
   <link name="RMShank_rx"/>
   <link name="RMShank_ry"/>
   <link name="RMShank">
      <inertial>
         <origin rpy="0 0 0" xyz="0 0 0"/>
         <mass value="1"/>
         <inertia ixx="0.0071027" ixy="-0.00059867" ixz="-2.9564e-05" iyy="0.0046194" iyz="6.6519e-05" izz="0.0080488"/>
      </inertial>
      <visual>
         <origin xyz="0 0 0" rpy="0 0 0"/>
         <geometry>
            <mesh filename="package://hpp-rbprm-corba/meshes/ant/RMShank.stl"/>
         </geometry>
         <material name="Gray"/>
      </visual>
      <collision>
         <origin xyz="0 0 0" rpy="0 0 0"/>
         <geometry>
            <mesh filename="package://hpp-rbprm-corba/meshes/ant/RMShank.stl"/>
         </geometry>
      </collision>
   </link>
   
   <link name="RMFoot_rx"/>
   <link name="RMFoot_ry"/>
   <link name="RMFoot">
      <inertial>
         <origin rpy="0 0 0" xyz="0 0 0"/>
         <mass value="1"/>
         <inertia ixx="0.0071027" ixy="-0.00059867" ixz="-2.9564e-05" iyy="0.0046194" iyz="6.6519e-05" izz="0.0080488"/>
      </inertial>
      <visual>
         <origin xyz="0 0 0" rpy="0 0 0"/>
         <geometry>
            <mesh filename="package://hpp-rbprm-corba/meshes/ant/RMFoot.stl"/>
         </geometry>
         <material name="Gray"/>
      </visual>
      <collision>
         <origin xyz="0 0 0" rpy="0 0 0"/>
         <geometry>
            <mesh filename="package://hpp-rbprm-corba/meshes/ant/RMFoot.stl"/>
         </geometry>
      </collision>
   </link>
   
   <link name="RBThigh_rx"/>
   <link name="RBThigh_ry"/>
   <link name="RBThigh">
      <inertial>
         <origin rpy="0 0 0" xyz="0 0 0"/>
         <mass value="1"/>
         <inertia ixx="0.0071027" ixy="-0.00059867" ixz="-2.9564e-05" iyy="0.0046194" iyz="6.6519e-05" izz="0.0080488"/>
      </inertial>
      <visual>
         <origin xyz="0 0 0" rpy="0 0 0"/>
         <geometry>
            <mesh filename="package://hpp-rbprm-corba/meshes/ant/RBThigh.stl"/>
         </geometry>
         <material name="Gray"/>
      </visual>
      <collision>
         <origin xyz="0 0 0" rpy="0 0 0"/>
         <geometry>
            <mesh filename="package://hpp-rbprm-corba/meshes/ant/RBThigh.stl"/>
         </geometry>
      </collision>
   </link>
   
   <link name="RBShank_rx"/>
   <link name="RBShank_ry"/>
   <link name="RBShank">
      <inertial>
         <origin rpy="0 0 0" xyz="0 0 0"/>
         <mass value="1"/>
         <inertia ixx="0.0071027" ixy="-0.00059867" ixz="-2.9564e-05" iyy="0.0046194" iyz="6.6519e-05" izz="0.0080488"/>
      </inertial>
      <visual>
         <origin xyz="0 0 0" rpy="0 0 0"/>
         <geometry>
            <mesh filename="package://hpp-rbprm-corba/meshes/ant/RBShank.stl"/>
         </geometry>
         <material name="Gray"/>
      </visual>
      <collision>
         <origin xyz="0 0 0" rpy="0 0 0"/>
         <geometry>
            <mesh filename="package://hpp-rbprm-corba/meshes/ant/RBShank.stl"/>
         </geometry>
      </collision>
   </link>
   
   <link name="RBFoot_rx"/>
   <link name="RBFoot_ry"/>
   <link name="RBFoot">
      <inertial>
         <origin rpy="0 0 0" xyz="0 0 0"/>
         <mass value="1"/>
         <inertia ixx="0.0071027" ixy="-0.00059867" ixz="-2.9564e-05" iyy="0.0046194" iyz="6.6519e-05" izz="0.0080488"/>
      </inertial>
      <visual>
         <origin xyz="0 0 0" rpy="0 0 0"/>
         <geometry>
            <mesh filename="package://hpp-rbprm-corba/meshes/ant/RBFoot.stl"/>
         </geometry>
         <material name="Gray"/>
      </visual>
      <collision>
         <origin xyz="0 0 0" rpy="0 0 0"/>
         <geometry>
            <mesh filename="package://hpp-rbprm-corba/meshes/ant/RBFoot.stl"/>
         </geometry>
      </collision>
   </link>

   <!-- end-effector spheres -->
  <link name="LFFootSphere">
      <visual>
         <origin xyz="0 0 0" rpy="0 0 0"/>
         <geometry>
            <sphere radius="0.005"/>
         </geometry>
         <material name="Blue"/>
      </visual>
   </link>
  <link name="LMFootSphere">
      <visual>
         <origin xyz="0 0 0" rpy="0 0 0"/>
         <geometry>
            <sphere radius="0.005"/>
         </geometry>
         <material name="Blue"/>
      </visual>
   </link>
  <link name="LBFootSphere">
      <visual>
         <origin xyz="0 0 0" rpy="0 0 0"/>
         <geometry>
            <sphere radius="0.005"/>
         </geometry>
         <material name="Blue"/>
      </visual>
   </link>
  <link name="RFFootSphere">
      <visual>
         <origin xyz="0 0 0" rpy="0 0 0"/>
         <geometry>
            <sphere radius="0.005"/>
         </geometry>
         <material name="Blue"/>
      </visual>
   </link>
  <link name="RMFootSphere">
      <visual>
         <origin xyz="0 0 0" rpy="0 0 0"/>
         <geometry>
            <sphere radius="0.005"/>
         </geometry>
         <material name="Blue"/>
      </visual>
   </link>
  <link name="RBFootSphere">
      <visual>
         <origin xyz="0 0 0" rpy="0 0 0"/>
         <geometry>
            <sphere radius="0.005"/>
         </geometry>
         <material name="Blue"/>
      </visual>
   </link>

   <!-- JOINTS -->
  <joint name="Abdomen_rx" type="revolute">
      <parent link="Thorax"/>
      <child link="Abdomen_rx"/>
      <origin rpy="0 0 0" xyz="0 0.1203 -0.0006"/>
      <axis xyz="1 0 0"/>
      <limit effort="0" lower="-0.2" upper="0.2" velocity="1.0"/>
   </joint>
   <joint name="Abdomen_ry" type="revolute">
      <parent link="Abdomen_rx"/>
      <child link="Abdomen_ry"/>
      <origin rpy="0 0 0" xyz="0 0 0"/>
      <axis xyz="0 1 0"/>
      <limit effort="0" lower="-0.2" upper="0.2" velocity="1.0"/>
   </joint>
   <joint name="Abdomen_rz" type="revolute">
      <parent link="Abdomen_rx"/>
      <child link="Abdomen"/>
      <origin rpy="0 0 0" xyz="0 0 0"/>
      <axis xyz="0 0 1"/>
      <limit effort="0" lower="-0.2" upper="0.2" velocity="1.0"/>
   </joint>
   <joint name="Head_rx" type="revolute">
      <parent link="Thorax"/>
      <child link="Head_rx"/>
      <origin rpy="0 0 0" xyz="0 -0.1029 0.0142"/>
      <axis xyz="1 0 0"/>
      <limit effort="0" lower="-0.2" upper="0.2" velocity="1.0"/>
   </joint>
   <joint name="Head_ry" type="revolute">
      <parent link="Head_rx"/>
      <child link="Head_ry"/>
      <origin rpy="0 0 0" xyz="0 0 0"/>
      <axis xyz="0 1 0"/>
      <limit effort="0" lower="-0.2" upper="0.2" velocity="1.0"/>
   </joint>
   <joint name="Head_rz" type="revolute">
      <parent link="Head_ry"/>
      <child link="Head"/>
      <origin rpy="0 0 0" xyz="0 0 0"/>
      <axis xyz="0 0 1"/>
      <limit effort="0" lower="-0.2" upper="0.2" velocity="1.0"/>
   </joint>
   
   <joint name="LAntena" type="fixed">
      <parent link="Head"/>
      <child link="LAntena"/>
      <origin rpy="0 0 0" xyz="0.0176 -0.1027 0.0225"/>
   </joint>
   <joint name="LAntenaFoot" type="fixed">
      <parent link="LAntena"/>
      <child link="LAntenaFoot"/>
      <origin rpy="0 0 0" xyz="0.0267 -0.0198 0.1006"/>
   </joint>
   
   <joint name="RAntena" type="fixed">
      <parent link="Head"/>
      <child link="RAntena"/>
      <origin rpy="0 0 0" xyz="-0.0168 -0.1029 0.0226"/>
   </joint>
   <joint name="RAntenaFoot" type="fixed">
      <parent link="RAntena"/>
      <child link="RAntenaFoot"/>
      <origin rpy="0 0 0" xyz="-0.0279 -0.0202 0.1006"/>
   </joint>

   
   <!-- left side -->
   <joint name="LFThigh_rx" type="revolute">
      <parent link="Thorax"/>
      <child link="LFThigh_rx"/>
      <origin rpy="0 0 0" xyz="0.0743 -0.0605 -0.0092"/>
      <axis xyz="1 0 0"/>
      <limit effort="0" lower="-1.2" upper="1.2" velocity="1.0"/>
   </joint>
   <joint name="LFThigh_ry" type="revolute">
      <parent link="LFThigh_rx"/>
      <child link="LFThigh_ry"/>
      <origin rpy="0 0 0" xyz="0 0 0"/>
      <axis xyz="0 1 0"/>
      <limit effort="0" lower="-1" upper="1" velocity="1.0"/>
   </joint>
   <joint name="LFThigh_rz" type="revolute">
      <parent link="LFThigh_ry"/>
      <child link="LFThigh"/>
      <origin rpy="0 0 0" xyz="0 0 0"/>
      <axis xyz="0 0 1"/>
      <limit effort="0" lower="-0.7" upper="0.7" velocity="1.0"/>
   </joint>
   <joint name="LFShank_rx" type="fixed">
      <parent link="LFThigh"/>
      <child link="LFShank_rx"/>
      <origin rpy="0 0 0" xyz="0.1217 -0.0662 0.0268"/>
      <!--<axis xyz="1 0 0"/>-->
      <!--<limit effort="0" lower="-0.4" upper="0.4" velocity="1.0"/>-->
   </joint>
   <joint name="LFShank_ry" type="revolute">
      <parent link="LFShank_rx"/>
      <child link="LFShank_ry"/>
      <origin rpy="0 0 0" xyz="0 0 0"/>
      <axis xyz="0 1 0"/>
      <limit effort="0" lower="-1" upper="1" velocity="1.0"/>
   </joint>
   <joint name="LFShank_rz" type="revolute">
      <parent link="LFShank_ry"/>
      <child link="LFShank"/>
      <origin rpy="0 0 0" xyz="0 0 0"/>
      <axis xyz="0 0 1"/>
      <limit effort="0" lower="-0.8" upper="0.8" velocity="1.0"/>
   </joint>
   <joint name="LFFoot_rx" type="revolute">
      <parent link="LFShank"/>
      <child link="LFFoot_rx"/>
      <origin rpy="0 0 0" xyz="0.0349 -0.0208 -0.0839"/>
      <axis xyz="1 0 0"/>
      <limit effort="0" lower="-0.4" upper="0.4" velocity="1.0"/>
   </joint>
   <joint name="LFFoot_ry" type="revolute">
      <parent link="LFFoot_rx"/>
      <child link="LFFoot_ry"/>
      <origin rpy="0 0 0" xyz="0 0 0"/>
      <axis xyz="0 1 0"/>
      <limit effort="0" lower="-0.2" upper="0.2" velocity="1.0"/>
   </joint>
   <joint name="LFFoot_rz" type="revolute">
      <parent link="LFFoot_ry"/>
      <child link="LFFoot"/>
      <origin rpy="0 0 0" xyz="0 0 0"/>
      <axis xyz="0 0 1"/>
      <limit effort="0" lower="-0.2" upper="0.2" velocity="1.0"/>
   </joint>
   
   <joint name="LMThigh_rx" type="revolute">
      <parent link="Thorax"/>
      <child link="LMThigh_rx"/>
      <origin rpy="0 0 0" xyz="0.0747 0.0011 -0.0074"/>
      <axis xyz="1 0 0"/>
      <limit effort="0" lower="-1.2" upper="1.2" velocity="1.0"/>
   </joint>
   <joint name="LMThigh_ry" type="revolute">
      <parent link="LMThigh_rx"/>
      <child link="LMThigh_ry"/>
      <origin rpy="0 0 0" xyz="0 0 0"/>
      <axis xyz="0 1 0"/>
      <limit effort="0" lower="-1" upper="1" velocity="1.0"/>
   </joint>
   <joint name="LMThigh_rz" type="revolute">
      <parent link="LMThigh_ry"/>
      <child link="LMThigh"/>
      <origin rpy="0 0 0" xyz="0 0 0"/>
      <axis xyz="0 0 1"/>
      <limit effort="0" lower="-0.7" upper="0.7" velocity="1.0"/>
   </joint>
   <joint name="LMShank_rx" type="fixed">
      <parent link="LMThigh"/>
      <child link="LMShank_rx"/>
      <origin rpy="0 0 0" xyz="0.1391 0.0483 0.0267"/>
      <!--<axis xyz="1 0 0"/>-->
      <!--<limit effort="0" lower="-0.4" upper="0.4" velocity="1.0"/>-->
   </joint>
   <joint name="LMShank_ry" type="revolute">
      <parent link="LMShank_rx"/>
      <child link="LMShank_ry"/>
      <origin rpy="0 0 0" xyz="0 0 0"/>
      <axis xyz="0 1 0"/>
      <limit effort="0" lower="-1" upper="1" velocity="1.0"/>
   </joint>
   <joint name="LMShank_rz" type="revolute">
      <parent link="LMShank_ry"/>
      <child link="LMShank"/>
      <origin rpy="0 0 0" xyz="0 0 0"/>
      <axis xyz="0 0 1"/>
      <limit effort="0" lower="-0.8" upper="0.8" velocity="1.0"/>
   </joint>
   <joint name="LMFoot_rx" type="revolute">
      <parent link="LMShank"/>
      <child link="LMFoot_rx"/>
      <origin rpy="0 0 0" xyz="0.0420 0.0142 -0.0892"/>
      <axis xyz="1 0 0"/>
      <limit effort="0" lower="-0.2" upper="0.2" velocity="1.0"/>
   </joint>
   <joint name="LMFoot_ry" type="revolute">
      <parent link="LMFoot_rx"/>
      <child link="LMFoot_ry"/>
      <origin rpy="0 0 0" xyz="0 0 0"/>
      <axis xyz="0 1 0"/>
      <limit effort="0" lower="-0.4" upper="0.4" velocity="1.0"/>
   </joint>
   <joint name="LMFoot_rz" type="revolute">
      <parent link="LMFoot_ry"/>
      <child link="LMFoot"/>
      <origin rpy="0 0 0" xyz="0 0 0"/>
      <axis xyz="0 0 1"/>
      <limit effort="0" lower="-0.2" upper="0.2" velocity="1.0"/>
   </joint>
   
   <joint name="LBThigh_rx" type="revolute">
      <parent link="Thorax"/>
      <child link="LBThigh_rx"/>
      <origin rpy="0 0 0" xyz="0.0624 0.0506 -0.0127"/>
      <axis xyz="1 0 0"/>
      <limit effort="0" lower="-1.2" upper="1.2" velocity="1.0"/>
   </joint>
   <joint name="LBThigh_ry" type="revolute">
      <parent link="LBThigh_rx"/>
      <child link="LBThigh_ry"/>
      <origin rpy="0 0 0" xyz="0 0 0"/>
      <axis xyz="0 1 0"/>
      <limit effort="0" lower="-1" upper="1" velocity="1.0"/>
   </joint>
   <joint name="LBThigh_rz" type="revolute">
      <parent link="LBThigh_ry"/>
      <child link="LBThigh"/>
      <origin rpy="0 0 0" xyz="0 0 0"/>
      <axis xyz="0 0 1"/>
      <limit effort="0" lower="-0.7" upper="0.7" velocity="1.0"/>
   </joint>
   <joint name="LBShank_rx" type="fixed">
      <parent link="LBThigh"/>
      <child link="LBShank_rx"/>
      <origin rpy="0 0 0" xyz="0.1238 0.1183 0.0330"/>
      <!--<axis xyz="1 0 0"/>-->
      <!--<limit effort="0" lower="-0.4" upper="0.4" velocity="1.0"/>-->
   </joint>
   <joint name="LBShank_ry" type="revolute">
      <parent link="LBShank_rx"/>
      <child link="LBShank_ry"/>
      <origin rpy="0 0 0" xyz="0 0 0"/>
      <axis xyz="0 1 0"/>
      <limit effort="0" lower="-1" upper="1" velocity="1.0"/>
   </joint>
   <joint name="LBShank_rz" type="revolute">
      <parent link="LBShank_ry"/>
      <child link="LBShank"/>
      <origin rpy="0 0 0" xyz="0 0 0"/>
      <axis xyz="0 0 1"/>
      <limit effort="0" lower="-0.8" upper="0.8" velocity="1.0"/>
   </joint>
   <joint name="LBFoot_rx" type="revolute">
      <parent link="LBShank"/>
      <child link="LBFoot_rx"/>
      <origin rpy="0 0 0" xyz="0.0387 0.0341 -0.0900"/>
      <axis xyz="1 0 0"/>
      <limit effort="0" lower="-0.2" upper="0.2" velocity="1.0"/>
   </joint>
   <joint name="LBFoot_ry" type="revolute">
      <parent link="LBFoot_rx"/>
      <child link="LBFoot_ry"/>
      <origin rpy="0 0 0" xyz="0 0 0"/>
      <axis xyz="0 1 0"/>
      <limit effort="0" lower="-0.4" upper="0.4" velocity="1.0"/>
   </joint>
   <joint name="LBFoot_rz" type="revolute">
      <parent link="LBFoot_ry"/>
      <child link="LBFoot"/>
      <origin rpy="0 0 0" xyz="0 0 0"/>
      <axis xyz="0 0 1"/>
      <limit effort="0" lower="-0.2" upper="0.2" velocity="1.0"/>
   </joint>
   
   <!-- right side -->
   <joint name="RFThigh_rx" type="revolute">
      <parent link="Thorax"/>
      <child link="RFThigh_rx"/>
      <origin rpy="0 0 0" xyz="-0.0703 -0.0587 -0.0088"/>
      <axis xyz="1 0 0"/>
      <limit effort="0" lower="-1.2" upper="1.2" velocity="1.0"/>
   </joint>
   <joint name="RFThigh_ry" type="revolute">
      <parent link="RFThigh_rx"/>
      <child link="RFThigh_ry"/>
      <origin rpy="0 0 0" xyz="0 0 0"/>
      <axis xyz="0 1 0"/>
      <limit effort="0" lower="-1" upper="1" velocity="1.0"/>
   </joint>
   <joint name="RFThigh_rz" type="revolute">
      <parent link="RFThigh_ry"/>
      <child link="RFThigh"/>
      <origin rpy="0 0 0" xyz="0 0 0"/>
      <axis xyz="0 0 1"/>
      <limit effort="0" lower="-0.7" upper="0.7" velocity="1.0"/>
   </joint>
   <joint name="RFShank_rx" type="fixed">
      <parent link="RFThigh"/>
      <child link="RFShank_rx"/>
      <origin rpy="0 0 0" xyz="-0.1258 -0.0680 0.0258"/>
      <!--<axis xyz="1 0 0"/>-->
      <!--<limit effort="0" lower="-0.4" upper="0.4" velocity="1.0"/>-->
   </joint>
   <joint name="RFShank_ry" type="revolute">
      <parent link="RFShank_rx"/>
      <child link="RFShank_ry"/>
      <origin rpy="0 0 0" xyz="0 0 0"/>
      <axis xyz="0 1 0"/>
      <limit effort="0" lower="-1" upper="1" velocity="1.0"/>
   </joint>
   <joint name="RFShank_rz" type="revolute">
      <parent link="RFShank_ry"/>
      <child link="RFShank"/>
      <origin rpy="0 0 0" xyz="0 0 0"/>
      <axis xyz="0 0 1"/>
      <limit effort="0" lower="-0.8" upper="0.8" velocity="1.0"/>
   </joint>
   <joint name="RFFoot_rx" type="revolute">
      <parent link="RFShank"/>
      <child link="RFFoot_rx"/>
      <origin rpy="0 0 0" xyz="-0.0347 -0.0205 -0.0847"/>
      <axis xyz="1 0 0"/>
      <limit effort="0" lower="-0.2" upper="0.2" velocity="1.0"/>
   </joint>
   <joint name="RFFoot_ry" type="revolute">
      <parent link="RFFoot_rx"/>
      <child link="RFFoot_ry"/>
      <origin rpy="0 0 0" xyz="0 0 0"/>
      <axis xyz="0 1 0"/>
      <limit effort="0" lower="-0.4" upper="0.4" velocity="1.0"/>
   </joint>
   <joint name="RFFoot_rz" type="revolute">
      <parent link="RFFoot_ry"/>
      <child link="RFFoot"/>
      <origin rpy="0 0 0" xyz="0 0 0"/>
      <axis xyz="0 0 1"/>
      <limit effort="0" lower="-0.2" upper="0.2" velocity="1.0"/>
   </joint>
   
   <joint name="RMThigh_rx" type="revolute">
      <parent link="Thorax"/>
      <child link="RMThigh_rx"/>
      <origin rpy="0 0 0" xyz="-0.0746 0.0016 -0.0073"/>
      <axis xyz="1 0 0"/>
      <limit effort="0" lower="-1.2" upper="1.2" velocity="1.0"/>
   </joint>
   <joint name="RMThigh_ry" type="revolute">
      <parent link="RMThigh_rx"/>
      <child link="RMThigh_ry"/>
      <origin rpy="0 0 0" xyz="0 0 0"/>
      <axis xyz="0 1 0"/>
      <limit effort="0" lower="-1" upper="1" velocity="1.0"/>
   </joint>
   <joint name="RMThigh_rz" type="revolute">
      <parent link="RMThigh_ry"/>
      <child link="RMThigh"/>
      <origin rpy="0 0 0" xyz="0 0 0"/>
      <axis xyz="0 0 1"/>
      <limit effort="0" lower="-0.7" upper="0.7" velocity="1.0"/>
   </joint>
   <joint name="RMShank_rx" type="fixed">
      <parent link="RMThigh"/>
      <child link="RMShank_rx"/>
      <origin rpy="0 0 0" xyz="-0.1387 0.0501 0.0266"/>
      <!--<axis xyz="1 0 0"/>-->
      <!--<limit effort="0" lower="-0.4" upper="0.4" velocity="1.0"/>-->
   </joint>
   <joint name="RMShank_ry" type="revolute">
      <parent link="RMShank_rx"/>
      <child link="RMShank_ry"/>
      <origin rpy="0 0 0" xyz="0 0 0"/>
      <axis xyz="0 1 0"/>
      <limit effort="0" lower="-1" upper="1" velocity="1.0"/>
   </joint>
   <joint name="RMShank_rz" type="revolute">
      <parent link="RMShank_ry"/>
      <child link="RMShank"/>
      <origin rpy="0 0 0" xyz="0 0 0"/>
      <axis xyz="0 0 1"/>
      <limit effort="0" lower="-0.8" upper="0.8" velocity="1.0"/>
   </joint>
   <joint name="RMFoot_rx" type="revolute">
      <parent link="RMShank"/>
      <child link="RMFoot_rx"/>
      <origin rpy="0 0 0" xyz="-0.0427 0.0128 -0.0895"/>
      <axis xyz="1 0 0"/>
      <limit effort="0" lower="-0.2" upper="0.2" velocity="1.0"/>
   </joint>
   <joint name="RMFoot_ry" type="revolute">
      <parent link="RMFoot_rx"/>
      <child link="RMFoot_ry"/>
      <origin rpy="0 0 0" xyz="0 0 0"/>
      <axis xyz="0 1 0"/>
      <limit effort="0" lower="-0.4" upper="0.4" velocity="1.0"/>
   </joint>
   <joint name="RMFoot_rz" type="revolute">
      <parent link="RMFoot_ry"/>
      <child link="RMFoot"/>
      <origin rpy="0 0 0" xyz="0 0 0"/>
      <axis xyz="0 0 1"/>
      <limit effort="0" lower="-0.2" upper="0.2" velocity="1.0"/>
   </joint>
   
   <joint name="RBThigh_rx" type="revolute">
      <parent link="Thorax"/>
      <child link="RBThigh_rx"/>
      <origin rpy="0 0 0" xyz="-0.0623 0.0509 -0.0132"/>
      <axis xyz="1 0 0"/>
      <limit effort="0" lower="-1.2" upper="1.2" velocity="1.0"/>
   </joint>
   <joint name="RBThigh_ry" type="revolute">
      <parent link="RBThigh_rx"/>
      <child link="RBThigh_ry"/>
      <origin rpy="0 0 0" xyz="0 0 0"/>
      <axis xyz="0 1 0"/>
      <limit effort="0" lower="-1" upper="1" velocity="1.0"/>
   </joint>
   <joint name="RBThigh_rz" type="revolute">
      <parent link="RBThigh_ry"/>
      <child link="RBThigh"/>
      <origin rpy="0 0 0" xyz="0 0 0"/>
      <axis xyz="0 0 1"/>
      <limit effort="0" lower="-0.7" upper="0.7" velocity="1.0"/>
   </joint>
   <joint name="RBShank_rx" type="fixed">
      <parent link="RBThigh"/>
      <child link="RBShank_rx"/>
      <origin rpy="0 0 0" xyz="-0.1239 0.1180 0.0334"/>
      <!--<axis xyz="1 0 0"/>-->
      <!--<limit effort="0" lower="-0.4" upper="0.4" velocity="1.0"/>-->
   </joint>
   <joint name="RBShank_ry" type="revolute">
      <parent link="RBShank_rx"/>
      <child link="RBShank_ry"/>
      <origin rpy="0 0 0" xyz="0 0 0"/>
      <axis xyz="0 1 0"/>
      <limit effort="0" lower="-1" upper="1" velocity="1.0"/>
   </joint>
   <joint name="RBShank_rz" type="revolute">
      <parent link="RBShank_ry"/>
      <child link="RBShank"/>
      <origin rpy="0 0 0" xyz="0 0 0"/>
      <axis xyz="0 0 1"/>
      <limit effort="0" lower="-0.8" upper="0.8" velocity="1.0"/>
   </joint>
   <joint name="RBFoot_rx" type="revolute">
      <parent link="RBShank"/>
      <child link="RBFoot_rx"/>
      <origin rpy="0 0 0" xyz="-0.0385 0.0344 -0.0907"/>
      <axis xyz="1 0 0"/>
      <limit effort="0" lower="-0.2" upper="0.2" velocity="1.0"/>
   </joint>
   <joint name="RBFoot_ry" type="revolute">
      <parent link="RBFoot_rx"/>
      <child link="RBFoot_ry"/>
      <origin rpy="0 0 0" xyz="0 0 0"/>
      <axis xyz="0 1 0"/>
      <limit effort="0" lower="-0.4" upper="0.4" velocity="1.0"/>
   </joint>
   <joint name="RBFoot_rz" type="revolute">
      <parent link="RBFoot_ry"/>
      <child link="RBFoot"/>
      <origin rpy="0 0 0" xyz="0 0 0"/>
      <axis xyz="0 0 1"/>
      <limit effort="0" lower="-0.2" upper="0.2" velocity="1.0"/>
   </joint>

 <!-- end-effector spheres -->
  <joint name="LFFootSphere" type="fixed">
      <parent link="LFFoot"/>
      <child link="LFFootSphere"/>
      <origin rpy="0 0 0" xyz="0.0724 -0.0430 -0.118"/> <!-- z - 0.002 -->
  </joint>
  <joint name="LMFootSphere" type="fixed">
      <parent link="LMFoot"/>
      <child link="LMFootSphere"/>
      <origin rpy="0 0 0" xyz="0.0925 0.0314 -0.1266"/>
  </joint>
  <joint name="LBFootSphere" type="fixed">
      <parent link="LBFoot"/>
      <child link="LBFootSphere"/>
      <origin rpy="0 0 0" xyz="0.0840 0.0771 -0.1303"/>
  </joint>
  <joint name="RFFootSphere" type="fixed">
      <parent link="RFFoot"/>
      <child link="RFFootSphere"/>
      <origin rpy="0 0 0" xyz="-0.0729 -0.0412 -0.1177"/>
  </joint>
  <joint name="RMFootSphere" type="fixed">
      <parent link="RMFoot"/>
      <child link="RMFootSphere"/>
      <origin rpy="0 0 0" xyz="-0.0923 0.0307 -0.1263"/>
  </joint>
  <joint name="RBFootSphere" type="fixed">
      <parent link="RBFoot"/>
      <child link="RBFootSphere"/>
      <origin rpy="0 0 0" xyz="-0.0852 0.0768 -0.1296"/>
  </joint>
</robot>
