<?xml version="1.0"?>
<robot name="ant_trunk">

  <link name="base_link"/>
  <joint name="base_link_J" type="fixed">
      <parent link="base_link"/>
      <child link="Thorax"/>
      <origin rpy="0 0 1.570796" xyz="0 0 0"/>
   </joint>

  <link name="Thorax">
      <inertial>
         <origin rpy="0 0 0" xyz="0 0 0"/>
         <mass value="1"/>
         <inertia ixx="0" ixy="0" ixz="0" iyy="0" iyz="0" izz="0"/>
      </inertial>
      <visual>
         <origin xyz="0 0 0" rpy="0 0 0"/>
         <geometry>
            <mesh filename="package://hpp-rbprm-corba/meshes/ant/Thorax_view.dae"/>
         </geometry>
      </visual>
      <collision>
         <origin xyz="0 0 0" rpy="0 0 0"/>
         <geometry>
            <mesh filename="package://hpp-rbprm-corba/meshes/ant/Thorax_box.stl"/>
         </geometry>
      </collision>
   </link>

   <!--<joint name="thorax_foot_rom_joint" type="fixed">
      <parent link="Thorax"/>
      <child link="thorax_foot_rom"/>
      <origin rpy="0 0 0" xyz="0 0 0"/>
   </joint>

  <link name="thorax_foot_rom">
      <visual>
         <origin xyz="0 0 0" rpy="0 0 0"/>
         <geometry>
            <mesh filename="package://hpp-rbprm-corba/meshes/ant/rbfoot_rom.stl"/>
         </geometry>
         <material name="Green"/>
      </visual>
   </link>-->

   <link name="Abdomen_rx"/>
   <link name="Abdomen_ry"/>
   <link name="Abdomen">
      <inertial>
         <origin rpy="0 0 0" xyz="0 0 0"/>
         <mass value="0"/>
         <inertia ixx="0" ixy="0" ixz="0" iyy="0" iyz="0" izz="0"/>
      </inertial>
      <visual>
         <origin xyz="0 0 0" rpy="0 0 0"/>
         <geometry>
            <mesh filename="package://hpp-rbprm-corba/meshes/ant/Abdomen_box.stl"/>
         </geometry>
      </visual>
      <collision>
         <origin xyz="0 0 0" rpy="0 0 0"/>
         <geometry>
            <mesh filename="package://hpp-rbprm-corba/meshes/ant/Abdomen_box.stl"/>
         </geometry>
      </collision>
   </link>
   <link name="Head_rx"/>
   <link name="Head_ry"/>
   <link name="Head">
      <inertial>
         <origin rpy="0 0 0" xyz="0 0 0"/>
         <mass value="4.2276"/>
         <inertia ixx="0.0071027" ixy="-0.00059867" ixz="-2.9564e-05" iyy="0.0046194" iyz="6.6519e-05" izz="0.0080488"/>
      </inertial>
      <visual>
         <origin xyz="0 0 0" rpy="0 0 0"/>
         <geometry>
            <mesh filename="package://hpp-rbprm-corba/meshes/ant/Skull_box.stl"/>
         </geometry>
      </visual>
      <collision>
         <origin xyz="0 0 0" rpy="0 0 0"/>
         <geometry>
            <mesh filename="package://hpp-rbprm-corba/meshes/ant/Skull_box.stl"/>
         </geometry>
      </collision>
   </link>

   <link name="LAntena">
      <inertial>
         <origin rpy="0 0 0" xyz="0 0 0"/>
         <mass value="1"/>
         <inertia ixx="0.0071027" ixy="-0.00059867" ixz="-2.9564e-05" iyy="0.0046194" iyz="6.6519e-05" izz="0.0080488"/>
      </inertial>
      <visual>
         <origin xyz="0 0 0" rpy="0 0 0"/>
         <geometry>
            <mesh filename="package://hpp-rbprm-corba/meshes/ant/LAntena.stl"/>
         </geometry>
      </visual>
      <collision>
         <origin xyz="0 0 0" rpy="0 0 0"/>
         <geometry>
            <mesh filename="package://hpp-rbprm-corba/meshes/ant/LAntena.stl"/>
         </geometry>
      </collision>
   </link>

   <link name="LAntenaFoot">
      <inertial>
         <origin rpy="0 0 0" xyz="0 0 0"/>
         <mass value="1"/>
         <inertia ixx="0.0071027" ixy="-0.00059867" ixz="-2.9564e-05" iyy="0.0046194" iyz="6.6519e-05" izz="0.0080488"/>
      </inertial>
      <visual>
         <origin xyz="0 0 0" rpy="0 0 0"/>
         <geometry>
            <mesh filename="package://hpp-rbprm-corba/meshes/ant/LAntenaFoot.stl"/>
         </geometry>
      </visual>
      <collision>
         <origin xyz="0 0 0" rpy="0 0 0"/>
         <geometry>
            <mesh filename="package://hpp-rbprm-corba/meshes/ant/LAntenaFoot.stl"/>
         </geometry>
      </collision>
   </link>
   
   <link name="RAntena">
      <inertial>
         <origin rpy="0 0 0" xyz="0 0 0"/>
         <mass value="1"/>
         <inertia ixx="0.0071027" ixy="-0.00059867" ixz="-2.9564e-05" iyy="0.0046194" iyz="6.6519e-05" izz="0.0080488"/>
      </inertial>
      <visual>
         <origin xyz="0 0 0" rpy="0 0 0"/>
         <geometry>
            <mesh filename="package://hpp-rbprm-corba/meshes/ant/RAntena.stl"/>
         </geometry>
      </visual>
      <collision>
         <origin xyz="0 0 0" rpy="0 0 0"/>
         <geometry>
            <mesh filename="package://hpp-rbprm-corba/meshes/ant/RAntena.stl"/>
         </geometry>
      </collision>
   </link>

   <link name="RAntenaFoot">
      <inertial>
         <origin rpy="0 0 0" xyz="0 0 0"/>
         <mass value="1"/>
         <inertia ixx="0.0071027" ixy="-0.00059867" ixz="-2.9564e-05" iyy="0.0046194" iyz="6.6519e-05" izz="0.0080488"/>
      </inertial>
      <visual>
         <origin xyz="0 0 0" rpy="0 0 0"/>
         <geometry>
            <mesh filename="package://hpp-rbprm-corba/meshes/ant/RAntenaFoot.stl"/>
         </geometry>
      </visual>
      <collision>
         <origin xyz="0 0 0" rpy="0 0 0"/>
         <geometry>
            <mesh filename="package://hpp-rbprm-corba/meshes/ant/RAntenaFoot.stl"/>
         </geometry>
      </collision>
   </link>

  <!-- JOINTS -->
   <joint name="Abdomen_rx" type="revolute">
      <parent link="Thorax"/>
      <child link="Abdomen_rx"/>
      <origin rpy="0 0 0" xyz="0 0.1203 -0.0006"/>
      <axis xyz="1 0 0"/>
      <limit effort="0" lower="-0.2" upper="0.2" velocity="1.0"/>
   </joint>
   <joint name="Abdomen_ry" type="revolute">
      <parent link="Abdomen_rx"/>
      <child link="Abdomen_ry"/>
      <origin rpy="0 0 0" xyz="0 0 0"/>
      <axis xyz="0 1 0"/>
      <limit effort="0" lower="-0.2" upper="0.2" velocity="1.0"/>
   </joint>
   <joint name="Abdomen_rz" type="revolute">
      <parent link="Abdomen_rx"/>
      <child link="Abdomen"/>
      <origin rpy="0 0 0" xyz="0 0 0"/>
      <axis xyz="0 0 1"/>
      <limit effort="0" lower="-0.2" upper="0.2" velocity="1.0"/>
   </joint>
   <joint name="Head_rx" type="revolute">
      <parent link="Thorax"/>
      <child link="Head_rx"/>
      <origin rpy="0 0 0" xyz="0 -0.1029 0.0142"/>
      <axis xyz="1 0 0"/>
      <limit effort="0" lower="-0.2" upper="0.2" velocity="1.0"/>
   </joint>
   <joint name="Head_ry" type="revolute">
      <parent link="Head_rx"/>
      <child link="Head_ry"/>
      <origin rpy="0 0 0" xyz="0 0 0"/>
      <axis xyz="0 1 0"/>
      <limit effort="0" lower="-0.2" upper="0.2" velocity="1.0"/>
   </joint>
   <joint name="Head_rz" type="revolute">
      <parent link="Head_ry"/>
      <child link="Head"/>
      <origin rpy="0 0 0" xyz="0 0 0"/>
      <axis xyz="0 0 1"/>
      <limit effort="0" lower="-0.2" upper="0.2" velocity="1.0"/>
   </joint>
   
   <joint name="LAntena" type="fixed">
      <parent link="Head"/>
      <child link="LAntena"/>
      <origin rpy="0 0 0" xyz="0.0176 -0.1027 0.0225"/>
   </joint>
   <joint name="LAntenaFoot" type="fixed">
      <parent link="LAntena"/>
      <child link="LAntenaFoot"/>
      <origin rpy="0 0 0" xyz="0.0267 -0.0198 0.1006"/>
   </joint>
   
   <joint name="RAntena" type="fixed">
      <parent link="Head"/>
      <child link="RAntena"/>
      <origin rpy="0 0 0" xyz="-0.0168 -0.1029 0.0226"/>
   </joint>
   <joint name="RAntenaFoot" type="fixed">
      <parent link="RAntena"/>
      <child link="RAntenaFoot"/>
      <origin rpy="0 0 0" xyz="-0.0279 -0.0202 0.1006"/>
   </joint>
</robot>
