<?xml version="1.0"?>
<robot name="ant_trunk">

  <link name="base_link"/>
  <joint name="base_link_J" type="fixed">
      <parent link="base_link"/>
      <child link="Thorax"/>
      <origin rpy="0 0 1.570796" xyz="0.001 -0.0382 -0.1982"/>
   </joint>

  <link name="Thorax">
      <inertial>
         <origin rpy="0 0 0" xyz="0 0 0"/>
         <mass value="1"/>
         <inertia ixx="0" ixy="0" ixz="0" iyy="0" iyz="0" izz="0"/>
      </inertial>
      <visual>
         <origin xyz="0 0 0" rpy="0 0 0"/>
         <geometry>
            <mesh filename="package://hpp-rbprm-corba/meshes/ant/Thorax_view.dae"/>
         </geometry>
      </visual>
      <collision>
         <origin xyz="0 0 0" rpy="0 0 0"/>
         <geometry>
            <mesh filename="package://hpp-rbprm-corba/meshes/ant/Thorax_box.stl"/>
         </geometry>
      </collision>
   </link>

   <!--<joint name="thorax_foot_rom_joint" type="fixed">
      <parent link="Thorax"/>
      <child link="thorax_foot_rom"/>
      <origin rpy="0 0 0" xyz="0 0 0"/>
   </joint>

  <link name="thorax_foot_rom">
      <visual>
         <origin xyz="0 0 0" rpy="0 0 0"/>
         <geometry>
            <mesh filename="package://hpp-rbprm-corba/meshes/ant/rbfoot_rom.stl"/>
         </geometry>
         <material name="Green"/>
      </visual>
   </link>-->

   <link name="ThoraxAbdomen_J1"/>
   <link name="ThoraxAbdomen_J2"/>
   <link name="Abdomen">
      <inertial>
         <origin rpy="0 0 0" xyz="0 0 0"/>
         <mass value="0"/>
         <inertia ixx="0" ixy="0" ixz="0" iyy="0" iyz="0" izz="0"/>
      </inertial>
      <visual>
         <origin xyz="0 0 0" rpy="0 0 0"/>
         <geometry>
            <mesh filename="package://hpp-rbprm-corba/meshes/ant/Abdomen.stl"/>
         </geometry>
      </visual>
      <collision>
         <origin xyz="0 0 0" rpy="0 0 0"/>
         <geometry>
            <mesh filename="package://hpp-rbprm-corba/meshes/ant/Abdomen_box.stl"/>
         </geometry>
      </collision>
   </link>
   <link name="ThoraxHead_J1"/>
   <link name="ThoraxHead_J2"/>
   <link name="Head">
      <inertial>
         <origin rpy="0 0 0" xyz="0 0 0"/>
         <mass value="4.2276"/>
         <inertia ixx="0.0071027" ixy="-0.00059867" ixz="-2.9564e-05" iyy="0.0046194" iyz="6.6519e-05" izz="0.0080488"/>
      </inertial>
      <visual>
         <origin xyz="0 0 0" rpy="0 0 0"/>
         <geometry>
            <mesh filename="package://hpp-rbprm-corba/meshes/ant/Skull.stl"/>
         </geometry>
      </visual>
      <collision>
         <origin xyz="0 0 0" rpy="0 0 0"/>
         <geometry>
            <mesh filename="package://hpp-rbprm-corba/meshes/ant/Skull_box.stl"/>
         </geometry>
      </collision>
   </link>

   <link name="HeadLAntena_J1"/>
   <link name="HeadLAntena_J2"/>
   <link name="LAntena">
      <inertial>
         <origin rpy="0 0 0" xyz="0 0 0"/>
         <mass value="1"/>
         <inertia ixx="0.0071027" ixy="-0.00059867" ixz="-2.9564e-05" iyy="0.0046194" iyz="6.6519e-05" izz="0.0080488"/>
      </inertial>
      <visual>
         <origin xyz="0 0 0" rpy="0 0 0"/>
         <geometry>
            <mesh filename="package://hpp-rbprm-corba/meshes/ant/LAntena.stl"/>
         </geometry>
      </visual>
      <collision>
         <origin xyz="0 0 0" rpy="0 0 0"/>
         <geometry>
            <mesh filename="package://hpp-rbprm-corba/meshes/ant/LAntena.stl"/>
         </geometry>
      </collision>
   </link>

   <link name="HeadLAntenaFoot_J1"/>
   <link name="HeadLAntenaFoot_J2"/>
   <link name="LAntenaFoot">
      <inertial>
         <origin rpy="0 0 0" xyz="0 0 0"/>
         <mass value="1"/>
         <inertia ixx="0.0071027" ixy="-0.00059867" ixz="-2.9564e-05" iyy="0.0046194" iyz="6.6519e-05" izz="0.0080488"/>
      </inertial>
      <visual>
         <origin xyz="0 0 0" rpy="0 0 0"/>
         <geometry>
            <mesh filename="package://hpp-rbprm-corba/meshes/ant/LAntenaFoot.stl"/>
         </geometry>
      </visual>
      <collision>
         <origin xyz="0 0 0" rpy="0 0 0"/>
         <geometry>
            <mesh filename="package://hpp-rbprm-corba/meshes/ant/LAntenaFoot.stl"/>
         </geometry>
      </collision>
   </link>
   
   <link name="HeadRAntena_J1"/>
   <link name="HeadRAntena_J2"/>
   <link name="RAntena">
      <inertial>
         <origin rpy="0 0 0" xyz="0 0 0"/>
         <mass value="1"/>
         <inertia ixx="0.0071027" ixy="-0.00059867" ixz="-2.9564e-05" iyy="0.0046194" iyz="6.6519e-05" izz="0.0080488"/>
      </inertial>
      <visual>
         <origin xyz="0 0 0" rpy="0 0 0"/>
         <geometry>
            <mesh filename="package://hpp-rbprm-corba/meshes/ant/RAntena.stl"/>
         </geometry>
      </visual>
      <collision>
         <origin xyz="0 0 0" rpy="0 0 0"/>
         <geometry>
            <mesh filename="package://hpp-rbprm-corba/meshes/ant/RAntena.stl"/>
         </geometry>
      </collision>
   </link>

   <link name="HeadRAntenaFoot_J1"/>
   <link name="HeadRAntenaFoot_J2"/>
   <link name="RAntenaFoot">
      <inertial>
         <origin rpy="0 0 0" xyz="0 0 0"/>
         <mass value="1"/>
         <inertia ixx="0.0071027" ixy="-0.00059867" ixz="-2.9564e-05" iyy="0.0046194" iyz="6.6519e-05" izz="0.0080488"/>
      </inertial>
      <visual>
         <origin xyz="0 0 0" rpy="0 0 0"/>
         <geometry>
            <mesh filename="package://hpp-rbprm-corba/meshes/ant/RAntenaFoot.stl"/>
         </geometry>
      </visual>
      <collision>
         <origin xyz="0 0 0" rpy="0 0 0"/>
         <geometry>
            <mesh filename="package://hpp-rbprm-corba/meshes/ant/RAntenaFoot.stl"/>
         </geometry>
      </collision>
   </link>

  <!-- JOINTS -->
  <joint name="ThoraxAbdomen_J1" type="revolute">
      <parent link="Thorax"/>
      <child link="ThoraxAbdomen_J1"/>
      <origin rpy="0 0 0" xyz="0 0.15853 0.19806"/>
      <axis xyz="1 0 0"/>
      <limit effort="0" lower="-0.2" upper="0.2" velocity="1.0"/>
   </joint>
   <joint name="ThoraxAbdomen_J2" type="revolute">
      <parent link="ThoraxAbdomen_J1"/>
      <child link="ThoraxAbdomen_J2"/>
      <origin rpy="0 0 0" xyz="0 0 0"/>
      <axis xyz="0 1 0"/>
      <limit effort="0" lower="-0.2" upper="0.2" velocity="1.0"/>
   </joint>
   <joint name="Abdomen" type="revolute">
      <parent link="ThoraxAbdomen_J1"/>
      <child link="Abdomen"/>
      <origin rpy="0 0 0" xyz="0 0 0"/>
      <axis xyz="0 0 1"/>
      <limit effort="0" lower="-0.2" upper="0.2" velocity="1.0"/>
   </joint>
   <joint name="ThoraxHead_J1" type="revolute">
      <parent link="Thorax"/>
      <child link="ThoraxHead_J1"/>
      <origin rpy="0 0 0" xyz="0 -0.06471 0.21279"/>
      <axis xyz="1 0 0"/>
      <limit effort="0" lower="-0.2" upper="0.2" velocity="1.0"/>
   </joint>
   <joint name="ThoraxHead_J2" type="revolute">
      <parent link="ThoraxHead_J1"/>
      <child link="ThoraxHead_J2"/>
      <origin rpy="0 0 0" xyz="0 0 0"/>
      <axis xyz="0 1 0"/>
      <limit effort="0" lower="-0.2" upper="0.2" velocity="1.0"/>
   </joint>
   <joint name="Head" type="revolute">
      <parent link="ThoraxHead_J2"/>
      <child link="Head"/>
      <origin rpy="0 0 0" xyz="0 0 0"/>
      <axis xyz="0 0 1"/>
      <limit effort="0" lower="-0.2" upper="0.2" velocity="1.0"/>
   </joint>
   
   <joint name="HeadLAntena_J1" type="revolute">
      <parent link="Head"/>
      <child link="HeadLAntena_J1"/>
      <origin rpy="0 0 0" xyz="0.0176 -0.1027 0.0225"/>
      <axis xyz="1 0 0"/>
      <limit effort="0" lower="-0.4" upper="0.4" velocity="1.0"/>
   </joint>
   <joint name="HeadLAntena_J2" type="revolute">
      <parent link="HeadLAntena_J1"/>
      <child link="HeadLAntena_J2"/>
      <origin rpy="0 0 0" xyz="0 0 0"/>
      <axis xyz="0 1 0"/>
      <limit effort="0" lower="-0.4" upper="0.4" velocity="1.0"/>
   </joint>
   <joint name="LAntena" type="revolute">
      <parent link="HeadLAntena_J2"/>
      <child link="LAntena"/>
      <origin rpy="0 0 0" xyz="0 0 0"/>
      <axis xyz="0 0 1"/>
      <limit effort="0" lower="-0.2" upper="0.2" velocity="1.0"/>
   </joint>
   <joint name="HeadLAntenaFoot_J1" type="revolute">
      <parent link="LAntena"/>
      <child link="HeadLAntenaFoot_J1"/>
      <origin rpy="0 0 0" xyz="0.0267 -0.0198 0.1006"/>
      <axis xyz="1 0 0"/>
      <limit effort="0" lower="-0.4" upper="0.4" velocity="1.0"/>
   </joint>
   <joint name="HeadLAntenaFoot_J2" type="revolute">
      <parent link="HeadLAntenaFoot_J1"/>
      <child link="HeadLAntenaFoot_J2"/>
      <origin rpy="0 0 0" xyz="0 0 0"/>
      <axis xyz="0 1 0"/>
      <limit effort="0" lower="-0.4" upper="0.4" velocity="1.0"/>
   </joint>
   <joint name="LAntenaFoot" type="revolute">
      <parent link="HeadLAntenaFoot_J2"/>
      <child link="LAntenaFoot"/>
      <origin rpy="0 0 0" xyz="0 0 0"/>
      <axis xyz="0 0 1"/>
      <limit effort="0" lower="-0.2" upper="0.2" velocity="1.0"/>
   </joint>
   
   <joint name="HeadRAntena_J1" type="revolute">
      <parent link="Head"/>
      <child link="HeadRAntena_J1"/>
      <origin rpy="0 0 0" xyz="-0.0168 -0.1029 0.0226"/>
      <axis xyz="1 0 0"/>
      <limit effort="0" lower="-0.4" upper="0.4" velocity="1.0"/>
   </joint>
   <joint name="HeadRAntena_J2" type="revolute">
      <parent link="HeadRAntena_J1"/>
      <child link="HeadRAntena_J2"/>
      <origin rpy="0 0 0" xyz="0 0 0"/>
      <axis xyz="0 1 0"/>
      <limit effort="0" lower="-0.4" upper="0.4" velocity="1.0"/>
   </joint>
   <joint name="RAntena" type="revolute">
      <parent link="HeadRAntena_J2"/>
      <child link="RAntena"/>
      <origin rpy="0 0 0" xyz="0 0 0"/>
      <axis xyz="0 0 1"/>
      <limit effort="0" lower="-0.2" upper="0.2" velocity="1.0"/>
   </joint>
   <joint name="HeadRAntenaFoot_J1" type="revolute">
      <parent link="RAntena"/>
      <child link="HeadRAntenaFoot_J1"/>
      <origin rpy="0 0 0" xyz="-0.0279 -0.0202 0.1006"/>
      <axis xyz="1 0 0"/>
      <limit effort="0" lower="-0.4" upper="0.4" velocity="1.0"/>
   </joint>
   <joint name="HeadRAntenaFoot_J2" type="revolute">
      <parent link="HeadRAntenaFoot_J1"/>
      <child link="HeadRAntenaFoot_J2"/>
      <origin rpy="0 0 0" xyz="0 0 0"/>
      <axis xyz="0 1 0"/>
      <limit effort="0" lower="-0.4" upper="0.4" velocity="1.0"/>
   </joint>
   <joint name="RAntenaFoot" type="revolute">
      <parent link="HeadRAntenaFoot_J2"/>
      <child link="RAntenaFoot"/>
      <origin rpy="0 0 0" xyz="0 0 0"/>
      <axis xyz="0 0 1"/>
      <limit effort="0" lower="-0.2" upper="0.2" velocity="1.0"/>
   </joint>
</robot>
