<?xml version="1.0"?>
<robot name="kangaroo">

  <material name="Blue"> <!-- for spheres -->
    <color rgba="0 0 1 0.5"/>
  </material>
  <material name="White">
    <color rgba="1 1 1 1"/>
  </material>
  <material name="Gray">
    <color rgba="0.6 0.6 0.6 0.4"/>
  </material>
  <material name="Green"> <!-- for ROMs -->
    <color rgba="0 1 0 1"/>
  </material>

  <link name="base_link"/>
  <joint name="base_link_J" type="fixed">
      <parent link="base_link"/>
      <child link="Pelvis"/>
      <origin rpy="0 0 0" xyz="0 0 0"/>
   </joint>

  <link name="virtualPelvis"/> <!-- for Blender Armature export -->
  <joint name="virtualPelvis" type="fixed">
      <parent link="base_link"/>
      <child link="virtualPelvis"/>
      <origin rpy="0 0 0" xyz="0 0 0"/>
  </joint>

  <link name="Pelvis">
      <inertial>
         <origin rpy="0 0 0" xyz="0 0 0"/>
         <mass value="1"/>
         <inertia ixx="0" ixy="0" ixz="0" iyy="0" iyz="0" izz="0"/>
      </inertial>
      <visual>
         <origin xyz="0 0 0" rpy="0 0 0"/>
         <geometry>
            <mesh filename="package://hpp-rbprm-corba/meshes/kangaroo/Pelvis.stl"/>
         </geometry>
		 <material name="Gray"/>
      </visual>
      <collision>
         <origin xyz="0 0 0" rpy="0 0 0"/>
         <geometry>
            <mesh filename="package://hpp-rbprm-corba/meshes/kangaroo/Pelvis.stl"/>
         </geometry>
      </collision>
   </link>  

   <!--<joint name="pelvis_lfoot_rom_joint" type="fixed">
      <parent link="Pelvis"/>
      <child link="lfoot_rom"/>
      <origin rpy="0 0 0" xyz="0 0 0"/>
   </joint>

  <link name="lfoot_rom">
      <visual>
         <origin xyz="0 0 0" rpy="0 0 0"/>
         <geometry>
            <mesh filename="package://hpp-rbprm-corba/meshes/kangaroo/lfoot_rom.stl"/>
         </geometry>
      </visual>
   </link>

   <joint name="pelvis_rfoot_rom_joint" type="fixed">
      <parent link="Pelvis"/>
      <child link="rfoot_rom"/>
      <origin rpy="0 0 0" xyz="0 0 0"/>
   </joint>

  <link name="rfoot_rom">
      <visual>
         <origin xyz="0 0 0" rpy="0 0 0"/>
         <geometry>
            <mesh filename="package://hpp-rbprm-corba/meshes/kangaroo/rfoot_rom.stl"/>
         </geometry>
      </visual>
   </link>-->

  <link name="Torso_rx"/>
  <link name="Torso_ry"/>
  <link name="Torso">
      <inertial>
         <origin rpy="0 0 0" xyz="0 0 0"/>
         <mass value="1"/>
         <inertia ixx="0" ixy="0" ixz="0" iyy="0" iyz="0" izz="0"/>
      </inertial>
      <visual>
         <origin xyz="0 0 0" rpy="0 0 0"/>
         <geometry>
            <mesh filename="package://hpp-rbprm-corba/meshes/kangaroo/Torso.stl"/>
         </geometry>
		 <material name="Gray"/>
      </visual>
      <collision>
         <origin xyz="0 0 0" rpy="0 0 0"/>
         <geometry>
            <mesh filename="package://hpp-rbprm-corba/meshes/kangaroo/Torso.stl"/>
         </geometry>
      </collision>
   </link>

   <link name="Head_rx"/>
   <link name="Head_ry"/>
   <link name="Head">
      <inertial>
         <origin rpy="0 0 0" xyz="0 0 0"/>
         <mass value="0"/>
         <inertia ixx="0" ixy="0" ixz="0" iyy="0" iyz="0" izz="0"/>
      </inertial>
      <visual>
         <origin xyz="0 0 0" rpy="0 0 0"/>
         <geometry>
            <mesh filename="package://hpp-rbprm-corba/meshes/kangaroo/Head.stl"/>
         </geometry>
		 <material name="Gray"/>
      </visual>
      <collision>
         <origin xyz="0 0 0" rpy="0 0 0"/>
         <geometry>
            <mesh filename="package://hpp-rbprm-corba/meshes/kangaroo/Head.stl"/>
         </geometry>
      </collision>
   </link>

   <link name="Tailbase_rx"/>
   <link name="Tailbase_ry"/>
   <link name="Tailbase">
      <inertial>
         <origin rpy="0 0 0" xyz="0 0 0"/>
         <mass value="0"/>
         <inertia ixx="0" ixy="0" ixz="0" iyy="0" iyz="0" izz="0"/>
      </inertial>
      <visual>
         <origin xyz="0 0 0" rpy="0 0 0"/>
         <geometry>
            <mesh filename="package://hpp-rbprm-corba/meshes/kangaroo/Tailbase.stl"/>
         </geometry>
		 <material name="Gray"/>
      </visual>
      <collision>
         <origin xyz="0 0 0" rpy="0 0 0"/>
         <geometry>
            <mesh filename="package://hpp-rbprm-corba/meshes/kangaroo/Tailbase.stl"/>
         </geometry>
      </collision>
   </link>

   <link name="Tail_rx"/>
   <link name="Tail_ry"/>
   <link name="Tail">
      <inertial>
         <origin rpy="0 0 0" xyz="0 0 0"/>
         <mass value="0"/>
         <inertia ixx="0" ixy="0" ixz="0" iyy="0" iyz="0" izz="0"/>
      </inertial>
      <visual>
         <origin xyz="0 0 0" rpy="0 0 0"/>
         <geometry>
            <mesh filename="package://hpp-rbprm-corba/meshes/kangaroo/Tail.stl"/>
         </geometry>
		 <material name="Gray"/>
      </visual>
      <collision>
         <origin xyz="0 0 0" rpy="0 0 0"/>
         <geometry>
            <mesh filename="package://hpp-rbprm-corba/meshes/kangaroo/Tail.stl"/>
         </geometry>
      </collision>
   </link>
   
   <!-- L = left, R = right-->
   <link name="LThigh_rx"/>
   <link name="LThigh_ry"/>
   <link name="LThigh">
      <inertial>
         <origin rpy="0 0 0" xyz="0 0 0"/>
         <mass value="1"/>
         <inertia ixx="0.0071027" ixy="-0.00059867" ixz="-2.9564e-05" iyy="0.0046194" iyz="6.6519e-05" izz="0.0080488"/>
      </inertial>
      <visual>
         <origin xyz="0 0 0" rpy="0 0 0"/>
         <geometry>
            <mesh filename="package://hpp-rbprm-corba/meshes/kangaroo/LThigh.stl"/>
         </geometry>
         <material name="Gray"/>
      </visual>
      <collision>
         <origin xyz="0 0 0" rpy="0 0 0"/>
         <geometry>
            <mesh filename="package://hpp-rbprm-corba/meshes/kangaroo/LThigh.stl"/>
         </geometry>
      </collision>
   </link>
   
   <link name="LShank_rx"/>
   <link name="LShank_ry"/>
   <link name="LShank">
      <inertial>
         <origin rpy="0 0 0" xyz="0 0 0"/>
         <mass value="1"/>
         <inertia ixx="0.0071027" ixy="-0.00059867" ixz="-2.9564e-05" iyy="0.0046194" iyz="6.6519e-05" izz="0.0080488"/>
      </inertial>
      <visual>
         <origin xyz="0 0 0" rpy="0 0 0"/>
         <geometry>
            <mesh filename="package://hpp-rbprm-corba/meshes/kangaroo/LShank.stl"/>
         </geometry>
         <material name="Gray"/>
      </visual>
      <collision>
         <origin xyz="0 0 0" rpy="0 0 0"/>
         <geometry>
            <mesh filename="package://hpp-rbprm-corba/meshes/kangaroo/LShank.stl"/>
         </geometry>
      </collision>
   </link>
   
   <link name="LFoot_rx"/>
   <link name="LFoot_ry"/>
   <link name="LFoot">
      <inertial>
         <origin rpy="0 0 0" xyz="0 0 0"/>
         <mass value="1"/>
         <inertia ixx="0.0071027" ixy="-0.00059867" ixz="-2.9564e-05" iyy="0.0046194" iyz="6.6519e-05" izz="0.0080488"/>
      </inertial>
      <visual>
         <origin xyz="0 0 0" rpy="0 0 0"/>
         <geometry>
            <mesh filename="package://hpp-rbprm-corba/meshes/kangaroo/LFoot.stl"/>
         </geometry>
         <material name="Gray"/>
      </visual>
      <collision>
         <origin xyz="0 0 0" rpy="0 0 0"/>
         <geometry>
            <mesh filename="package://hpp-rbprm-corba/meshes/kangaroo/LFoot.stl"/>
         </geometry>
      </collision>
   </link>
   <link name="LFootToe">
      <inertial>
         <origin rpy="0 0 0" xyz="0 0 0"/>
         <mass value="1"/>
         <inertia ixx="0.0071027" ixy="-0.00059867" ixz="-2.9564e-05" iyy="0.0046194" iyz="6.6519e-05" izz="0.0080488"/>
      </inertial>
      <visual>
         <origin xyz="0 0 0" rpy="0 0 0"/>
         <geometry>
            <mesh filename="package://hpp-rbprm-corba/meshes/kangaroo/LFootToe.stl"/>
         </geometry>
         <material name="Gray"/>
      </visual>
      <collision>
         <origin xyz="0 0 0" rpy="0 0 0"/>
         <geometry>
            <mesh filename="package://hpp-rbprm-corba/meshes/kangaroo/LFootToe.stl"/>
         </geometry>
      </collision>
   </link>
   
   <link name="KangarooLFootSphere">
      <visual>
         <origin xyz="0 0 0" rpy="0 0 0"/>
         <geometry>
            <sphere radius="0.01"/>
         </geometry>
         <material name="Blue"/>
      </visual>
   </link>
   
   <link name="RThigh_rx"/>
   <link name="RThigh_ry"/>
   <link name="RThigh">
      <inertial>
         <origin rpy="0 0 0" xyz="0 0 0"/>
         <mass value="1"/>
         <inertia ixx="0.0071027" ixy="-0.00059867" ixz="-2.9564e-05" iyy="0.0046194" iyz="6.6519e-05" izz="0.0080488"/>
      </inertial>
      <visual>
         <origin xyz="0 0 0" rpy="0 0 0"/>
         <geometry>
            <mesh filename="package://hpp-rbprm-corba/meshes/kangaroo/RThigh.stl"/>
         </geometry>
         <material name="Gray"/>
      </visual>
      <collision>
         <origin xyz="0 0 0" rpy="0 0 0"/>
         <geometry>
            <mesh filename="package://hpp-rbprm-corba/meshes/kangaroo/RThigh.stl"/>
         </geometry>
      </collision>
   </link>
   
   <link name="RShank_rx"/>
   <link name="RShank_ry"/>
   <link name="RShank">
      <inertial>
         <origin rpy="0 0 0" xyz="0 0 0"/>
         <mass value="1"/>
         <inertia ixx="0.0071027" ixy="-0.00059867" ixz="-2.9564e-05" iyy="0.0046194" iyz="6.6519e-05" izz="0.0080488"/>
      </inertial>
      <visual>
         <origin xyz="0 0 0" rpy="0 0 0"/>
         <geometry>
            <mesh filename="package://hpp-rbprm-corba/meshes/kangaroo/RShank.stl"/>
         </geometry>
         <material name="Gray"/>
      </visual>
      <collision>
         <origin xyz="0 0 0" rpy="0 0 0"/>
         <geometry>
            <mesh filename="package://hpp-rbprm-corba/meshes/kangaroo/RShank.stl"/>
         </geometry>
      </collision>
   </link>
   
   <link name="RFoot_rx"/>
   <link name="RFoot_ry"/>
   <link name="RFoot">
      <inertial>
         <origin rpy="0 0 0" xyz="0 0 0"/>
         <mass value="1"/>
         <inertia ixx="0.0071027" ixy="-0.00059867" ixz="-2.9564e-05" iyy="0.0046194" iyz="6.6519e-05" izz="0.0080488"/>
      </inertial>
      <visual>
         <origin xyz="0 0 0" rpy="0 0 0"/>
         <geometry>
            <mesh filename="package://hpp-rbprm-corba/meshes/kangaroo/RFoot.stl"/>
         </geometry>
         <material name="Gray"/>
      </visual>
      <collision>
         <origin xyz="0 0 0" rpy="0 0 0"/>
         <geometry>
            <mesh filename="package://hpp-rbprm-corba/meshes/kangaroo/RFoot.stl"/>
         </geometry>
      </collision>
   </link>
   <link name="RFootToe">
      <inertial>
         <origin rpy="0 0 0" xyz="0 0 0"/>
         <mass value="1"/>
         <inertia ixx="0.0071027" ixy="-0.00059867" ixz="-2.9564e-05" iyy="0.0046194" iyz="6.6519e-05" izz="0.0080488"/>
      </inertial>
      <visual>
         <origin xyz="0 0 0" rpy="0 0 0"/>
         <geometry>
            <mesh filename="package://hpp-rbprm-corba/meshes/kangaroo/RFootToe.stl"/>
         </geometry>
         <material name="Gray"/>
      </visual>
      <collision>
         <origin xyz="0 0 0" rpy="0 0 0"/>
         <geometry>
            <mesh filename="package://hpp-rbprm-corba/meshes/kangaroo/RFootToe.stl"/>
         </geometry>
      </collision>
   </link>
   
   <link name="KangarooRFootSphere">
      <visual>
         <origin xyz="0 0 0" rpy="0 0 0"/>
         <geometry>
            <sphere radius="0.01"/>
         </geometry>
         <material name="Blue"/>
      </visual>
   </link>
  
   <link name="LArm_rx"/>
   <link name="LArm_ry"/>
   <link name="LArm">
      <inertial>
         <origin rpy="0 0 0" xyz="0 0 0"/>
         <mass value="1"/>
         <inertia ixx="0.0071027" ixy="-0.00059867" ixz="-2.9564e-05" iyy="0.0046194" iyz="6.6519e-05" izz="0.0080488"/>
      </inertial>
      <visual>
         <origin xyz="0 0 0" rpy="0 0 0"/>
         <geometry>
            <mesh filename="package://hpp-rbprm-corba/meshes/kangaroo/LArm.stl"/>
         </geometry>
         <material name="Gray"/>
      </visual>
      <collision>
         <origin xyz="0 0 0" rpy="0 0 0"/>
         <geometry>
            <mesh filename="package://hpp-rbprm-corba/meshes/kangaroo/LArm.stl"/>
         </geometry>
      </collision>
   </link>
   
   <link name="LForearm_rx"/>
   <link name="LForearm_ry"/>
   <link name="LForearm">
      <inertial>
         <origin rpy="0 0 0" xyz="0 0 0"/>
         <mass value="1"/>
         <inertia ixx="0.0071027" ixy="-0.00059867" ixz="-2.9564e-05" iyy="0.0046194" iyz="6.6519e-05" izz="0.0080488"/>
      </inertial>
      <visual>
         <origin xyz="0 0 0" rpy="0 0 0"/>
         <geometry>
            <mesh filename="package://hpp-rbprm-corba/meshes/kangaroo/LForearm.stl"/>
         </geometry>
         <material name="Gray"/>
      </visual>
      <collision>
         <origin xyz="0 0 0" rpy="0 0 0"/>
         <geometry>
            <mesh filename="package://hpp-rbprm-corba/meshes/kangaroo/LForearm.stl"/>
         </geometry>
      </collision>
   </link>

   <link name="LHand_rx"/>
   <link name="LHand_ry"/>
   <link name="LHand">
      <inertial>
         <origin rpy="0 0 0" xyz="0 0 0"/>
         <mass value="1"/>
         <inertia ixx="0.0071027" ixy="-0.00059867" ixz="-2.9564e-05" iyy="0.0046194" iyz="6.6519e-05" izz="0.0080488"/>
      </inertial>
      <visual>
         <origin xyz="0 0 0" rpy="0 0 0"/>
         <geometry>
            <mesh filename="package://hpp-rbprm-corba/meshes/kangaroo/LHand.stl"/>
         </geometry>
         <material name="Gray"/>
      </visual>
      <collision>
         <origin xyz="0 0 0" rpy="0 0 0"/>
         <geometry>
            <mesh filename="package://hpp-rbprm-corba/meshes/kangaroo/LHand.stl"/>
         </geometry>
      </collision>
   </link>
   <link name="KangarooLHandSphere">
      <visual>
         <origin xyz="0 0 0" rpy="0 0 0"/>
         <geometry>
            <sphere radius="0.01"/>
         </geometry>
         <material name="Blue"/>
      </visual>
   </link>   
   
   <link name="RArm_rx"/>
   <link name="RArm_ry"/>
   <link name="RArm">
      <inertial>
         <origin rpy="0 0 0" xyz="0 0 0"/>
         <mass value="1"/>
         <inertia ixx="0.0071027" ixy="-0.00059867" ixz="-2.9564e-05" iyy="0.0046194" iyz="6.6519e-05" izz="0.0080488"/>
      </inertial>
      <visual>
         <origin xyz="0 0 0" rpy="0 0 0"/>
         <geometry>
            <mesh filename="package://hpp-rbprm-corba/meshes/kangaroo/RArm.stl"/>
         </geometry>
         <material name="Gray"/>
      </visual>
      <collision>
         <origin xyz="0 0 0" rpy="0 0 0"/>
         <geometry>
            <mesh filename="package://hpp-rbprm-corba/meshes/kangaroo/RArm.stl"/>
         </geometry>
      </collision>
   </link>
   
   <link name="RForearm_rx"/>
   <link name="RForearm_ry"/>
   <link name="RForearm">
      <inertial>
         <origin rpy="0 0 0" xyz="0 0 0"/>
         <mass value="1"/>
         <inertia ixx="0.0071027" ixy="-0.00059867" ixz="-2.9564e-05" iyy="0.0046194" iyz="6.6519e-05" izz="0.0080488"/>
      </inertial>
      <visual>
         <origin xyz="0 0 0" rpy="0 0 0"/>
         <geometry>
            <mesh filename="package://hpp-rbprm-corba/meshes/kangaroo/RForearm.stl"/>
         </geometry>
         <material name="Gray"/>
      </visual>
      <collision>
         <origin xyz="0 0 0" rpy="0 0 0"/>
         <geometry>
            <mesh filename="package://hpp-rbprm-corba/meshes/kangaroo/RForearm.stl"/>
         </geometry>
      </collision>
   </link>

   <link name="RHand_rx"/>
   <link name="RHand_ry"/>
   <link name="RHand">
      <inertial>
         <origin rpy="0 0 0" xyz="0 0 0"/>
         <mass value="1"/>
         <inertia ixx="0.0071027" ixy="-0.00059867" ixz="-2.9564e-05" iyy="0.0046194" iyz="6.6519e-05" izz="0.0080488"/>
      </inertial>
      <visual>
         <origin xyz="0 0 0" rpy="0 0 0"/>
         <geometry>
            <mesh filename="package://hpp-rbprm-corba/meshes/kangaroo/RHand.stl"/>
         </geometry>
         <material name="Gray"/>
      </visual>
      <collision>
         <origin xyz="0 0 0" rpy="0 0 0"/>
         <geometry>
            <mesh filename="package://hpp-rbprm-corba/meshes/kangaroo/RHand.stl"/>
         </geometry>
      </collision>
   </link>
   <link name="KangarooRHandSphere">
      <visual>
         <origin xyz="0 0 0" rpy="0 0 0"/>
         <geometry>
            <sphere radius="0.01"/>
         </geometry>
         <material name="Blue"/>
      </visual>
   </link>
   

   <!-- JOINTS -->
  <joint name="A_Torso_rx" type="revolute"> <!-- "A_" to put trunk joints before limb joints in joint chain built by ROS URDF parser -->
      <parent link="Pelvis"/>
      <child link="Torso_rx"/>
      <origin rpy="0 0 0" xyz="0.007 0.0012 0.0982"/>
      <axis xyz="1 0 0"/>
      <limit effort="0" lower="-0.1" upper="0.1" velocity="1.0"/>
   </joint>
   <joint name="Torso_ry" type="revolute">
      <parent link="Torso_rx"/>
      <child link="Torso_ry"/>
      <origin rpy="0 0 0" xyz="0 0 0"/>
      <axis xyz="0 1 0"/>
      <limit effort="0" lower="-0.4" upper="0.7" velocity="1.0"/>
   </joint>
   <joint name="Torso_rz" type="revolute">
      <parent link="Torso_ry"/>
      <child link="Torso"/>
      <origin rpy="0 0 0" xyz="0 0 0"/>
      <axis xyz="0 0 1"/>
      <limit effort="0" lower="-0.3" upper="0.3" velocity="1.0"/>
   </joint>
  <joint name="Head_rx" type="revolute">
      <parent link="Torso"/>
      <child link="Head_rx"/>
      <origin rpy="0 0 0" xyz="0.2629 -0.0018 0.299"/>
      <axis xyz="1 0 0"/>
      <limit effort="0" lower="-0.1" upper="0.1" velocity="1.0"/>
   </joint>
   <joint name="Head_ry" type="revolute">
      <parent link="Head_rx"/>
      <child link="Head_ry"/>
      <origin rpy="0 0 0" xyz="0 0 0"/>
      <axis xyz="0 1 0"/>
      <limit effort="0" lower="-0.3" upper="0.3" velocity="1.0"/>
   </joint>
   <joint name="Head_rz" type="revolute">
      <parent link="Head_ry"/>
      <child link="Head"/>
      <origin rpy="0 0 0" xyz="0 0 0"/>
      <axis xyz="0 0 1"/>
      <limit effort="0" lower="-0.4" upper="0.4" velocity="1.0"/>
   </joint>
  <joint name="A_Tailbase_rx" type="revolute"> <!-- "A_" to put trunk joints before limb joints in joint chain built by ROS URDF parser -->
      <parent link="Pelvis"/>
      <child link="Tailbase_rx"/>
      <origin rpy="0 0 0" xyz="-0.0982 -0.001 -0.1713"/>
      <axis xyz="1 0 0"/>
      <limit effort="0" lower="-0.2" upper="0.2" velocity="1.0"/>
   </joint>
   <joint name="Tailbase_ry" type="revolute">
      <parent link="Tailbase_rx"/>
      <child link="Tailbase_ry"/>
      <origin rpy="0 0 0" xyz="0 0 0"/>
      <axis xyz="0 1 0"/>
      <limit effort="0" lower="-0.4" upper="0.5" velocity="1.0"/>
   </joint>
   <joint name="Tailbase_rz" type="revolute">
      <parent link="Tailbase_ry"/>
      <child link="Tailbase"/>
      <origin rpy="0 0 0" xyz="0 0 0"/>
      <axis xyz="0 0 1"/>
      <limit effort="0" lower="-0.2" upper="0.2" velocity="1.0"/>
   </joint>
  <joint name="Tail_rx" type="revolute">
      <parent link="Tailbase"/>
      <child link="Tail_rx"/>
      <origin rpy="0 0 0" xyz="-0.2284 0.0005 -0.2151"/>
      <axis xyz="1 0 0"/>
      <limit effort="0" lower="-0.2" upper="0.2" velocity="1.0"/>
   </joint>
   <joint name="Tail_ry" type="revolute">
      <parent link="Tail_rx"/>
      <child link="Tail_ry"/>
      <origin rpy="0 0 0" xyz="0 0 0"/>
      <axis xyz="0 1 0"/>
      <limit effort="0" lower="-0.4" upper="0.5" velocity="1.0"/>
   </joint>
   <joint name="Tail_rz" type="revolute">
      <parent link="Tail_ry"/>
      <child link="Tail"/>
      <origin rpy="0 0 0" xyz="0 0 0"/>
      <axis xyz="0 0 1"/>
      <limit effort="0" lower="-0.2" upper="0.2" velocity="1.0"/>
   </joint>
   
   <!-- left side -->
  <joint name="LThigh_rx" type="revolute">
      <parent link="Pelvis"/>
      <child link="LThigh_rx"/>
      <origin rpy="0 0 0" xyz="0.0278 0.1452 -0.072"/>
      <axis xyz="1 0 0"/>
      <limit effort="0" lower="-0.2" upper="0.2" velocity="1.0"/>
   </joint>
   <joint name="LThigh_ry" type="revolute">
      <parent link="LThigh_rx"/>
      <child link="LThigh_ry"/>
      <origin rpy="0 0 0" xyz="0 0 0"/>
      <axis xyz="0 1 0"/>
      <limit effort="0" lower="-0.6" upper="1.0" velocity="1.0"/>
   </joint>
   <joint name="LThigh_rz" type="revolute">
      <parent link="LThigh_ry"/>
      <child link="LThigh"/>
      <origin rpy="0 0 0" xyz="0 0 0"/>
      <axis xyz="0 0 1"/>
      <limit effort="0" lower="-0.3" upper="0.4" velocity="1.0"/>
   </joint>
  <joint name="LShank_rx" type="fixed">
      <parent link="LThigh"/>
      <child link="LShank_rx"/>
      <origin rpy="0 0 0" xyz="0.0504 0.0468 -0.016"/>
   </joint>
   <joint name="LShank_ry" type="revolute">
      <parent link="LShank_rx"/>
      <child link="LShank_ry"/>
      <origin rpy="0 0 0" xyz="0 0 0"/>
      <axis xyz="0 1 0"/>
      <limit effort="0" lower="-0.5" upper="0.8" velocity="1.0"/>
   </joint>
   <joint name="LShank_rz" type="fixed">
      <parent link="LShank_ry"/>
      <child link="LShank"/>
      <origin rpy="0 0 0" xyz="0 0 0"/>
   </joint>
  <joint name="LFoot_rx" type="fixed">
      <parent link="LShank"/>
      <child link="LFoot_rx"/>
      <origin rpy="0 0 0" xyz="0.0075 -0.0227 -0.2986"/>
   </joint>
   <joint name="LFoot_ry" type="revolute">
      <parent link="LFoot_rx"/>
      <child link="LFoot_ry"/>
      <origin rpy="0 0 0" xyz="0 0 0"/>
      <axis xyz="0 1 0"/>
      <limit effort="0" lower="-1.0" upper="0.8" velocity="1.0"/>
   </joint>
   <joint name="LFoot_rz" type="fixed">
      <parent link="LFoot_ry"/>
      <child link="LFoot"/>
      <origin rpy="0 0 0" xyz="0 0 0"/>
   </joint>
   <joint name="LFootToe_ry" type="revolute">
      <parent link="LFoot"/>
      <child link="LFootToe"/>
      <origin rpy="0 0 0" xyz="0.1256 0.0207 -0.0258"/>
      <axis xyz="0 1 0"/>
      <limit effort="0" lower="-1" upper="0.4" velocity="1.0"/>
   </joint>
   <joint name="KangarooLFootSphere" type="fixed">
      <parent link="LFootToe"/>
      <child link="KangarooLFootSphere"/>
      <origin rpy="0 0 0" xyz="0.0758 0.0148 -0.0377"/>
   </joint>
   
  <joint name="LArm_rx" type="revolute">
      <parent link="Torso"/>
      <child link="LArm_rx"/>
      <origin rpy="0 0 0" xyz="0.1467 0.0828 0.0579"/>
      <axis xyz="1 0 0"/>
      <limit effort="0" lower="-0.1" upper="0.3" velocity="1.0"/>
   </joint>
   <joint name="LArm_ry" type="revolute">
      <parent link="LArm_rx"/>
      <child link="LArm_ry"/>
      <origin rpy="0 0 0" xyz="0 0 0"/>
      <axis xyz="0 1 0"/>
      <limit effort="0" lower="-0.5" upper="0.2" velocity="1.0"/>
   </joint>
   <joint name="LArm_rz" type="revolute">
      <parent link="LArm_ry"/>
      <child link="LArm"/>
      <origin rpy="0 0 0" xyz="0 0 0"/>
      <axis xyz="0 0 1"/>
      <limit effort="0" lower="-0.2" upper="0.2" velocity="1.0"/>
   </joint>
  <joint name="LForearm_rx" type="fixed">
      <parent link="LArm"/>
      <child link="LForearm_rx"/>
      <origin rpy="0 0 0" xyz="0.0081 0.0262 -0.084"/>
   </joint>
   <joint name="LForearm_ry" type="revolute">
      <parent link="LForearm_rx"/>
      <child link="LForearm_ry"/>
      <origin rpy="0 0 0" xyz="0 0 0"/>
      <axis xyz="0 1 0"/>
      <limit effort="0" lower="-0.6" upper="0.2" velocity="1.0"/>
   </joint>
   <joint name="LForearm_rz" type="fixed">
      <parent link="LForearm_ry"/>
      <child link="LForearm"/>
      <origin rpy="0 0 0" xyz="0 0 0"/>
   </joint>
  <joint name="LHand_rx" type="revolute">
      <parent link="LForearm"/>
      <child link="LHand_rx"/>
      <origin rpy="0 0 0" xyz="0.1102 0.0017 -0.1538"/>
      <axis xyz="1 0 0"/>
      <limit effort="0" lower="-0.2" upper="0.2" velocity="1.0"/>
   </joint>
   <joint name="LHand_ry" type="revolute">
      <parent link="LHand_rx"/>
      <child link="LHand_ry"/>
      <origin rpy="0 0 0" xyz="0 0 0"/>
      <axis xyz="0 1 0"/>
      <limit effort="0" lower="-0.1" upper="0.1" velocity="1.0"/>
   </joint>
   <joint name="LHand_rz" type="fixed">
      <parent link="LHand_ry"/>
      <child link="LHand"/>
      <origin rpy="0 0 0" xyz="0 0 0"/>
   </joint>
   <joint name="KangarooLHandSphere" type="fixed">
      <parent link="LHand"/>
      <child link="KangarooLHandSphere"/>
      <origin rpy="0 0 0" xyz="0 0 0"/>
   </joint>
   
   <!-- right side -->
  <joint name="RThigh_rx" type="revolute">
      <parent link="Pelvis"/>
      <child link="RThigh_rx"/>
      <origin rpy="0 0 0" xyz="0.0278 -0.15 -0.072"/>
      <axis xyz="1 0 0"/>
      <limit effort="0" lower="-0.2" upper="0.2" velocity="1.0"/>
   </joint>
   <joint name="RThigh_ry" type="revolute">
      <parent link="RThigh_rx"/>
      <child link="RThigh_ry"/>
      <origin rpy="0 0 0" xyz="0 0 0"/>
      <axis xyz="0 1 0"/>
      <limit effort="0" lower="-0.6" upper="1.0" velocity="1.0"/>
   </joint>
   <joint name="RThigh_rz" type="revolute">
      <parent link="RThigh_ry"/>
      <child link="RThigh"/>
      <origin rpy="0 0 0" xyz="0 0 0"/>
      <axis xyz="0 0 1"/>
      <limit effort="0" lower="-0.4" upper="0.3" velocity="1.0"/>
   </joint>
  <joint name="RShank_rx" type="fixed">
      <parent link="RThigh"/>
      <child link="RShank_rx"/>
      <origin rpy="0 0 0" xyz="0.0575 -0.0409 -0.0212"/>
   </joint>
   <joint name="RShank_ry" type="revolute">
      <parent link="RShank_rx"/>
      <child link="RShank_ry"/>
      <origin rpy="0 0 0" xyz="0 0 0"/>
      <axis xyz="0 1 0"/>
      <limit effort="0" lower="-0.5" upper="0.8" velocity="1.0"/>
   </joint>
   <joint name="RShank_rz" type="fixed">
      <parent link="RShank_ry"/>
      <child link="RShank"/>
      <origin rpy="0 0 0" xyz="0 0 0"/>
   </joint>
  <joint name="RFoot_rx" type="fixed">
      <parent link="RShank"/>
      <child link="RFoot_rx"/>
      <origin rpy="0 0 0" xyz="0.0026 0.0147 -0.2965"/>
   </joint>
   <joint name="RFoot_ry" type="revolute">
      <parent link="RFoot_rx"/>
      <child link="RFoot_ry"/>
      <origin rpy="0 0 0" xyz="0 0 0"/>
      <axis xyz="0 1 0"/>
      <limit effort="0" lower="-1.0" upper="0.8" velocity="1.0"/>
   </joint>
   <joint name="RFoot_rz" type="fixed">
      <parent link="RFoot_ry"/>
      <child link="RFoot"/>
      <origin rpy="0 0 0" xyz="0 0 0"/>
   </joint>
   <joint name="RFootToe_ry" type="revolute">
      <parent link="RFoot"/>
      <child link="RFootToe"/>
      <origin rpy="0 0 0" xyz="0.1274 -0.0159 -0.0219"/>
      <axis xyz="0 1 0"/>
      <limit effort="0" lower="-1.0" upper="0.4" velocity="1.0"/>
   </joint>
   <joint name="KangarooRFootSphere" type="fixed">
      <parent link="RFootToe"/>
      <child link="KangarooRFootSphere"/>
      <origin rpy="0 0 0" xyz="0.0719 -0.018 -0.0384"/>
   </joint>
   
  <joint name="RArm_rx" type="revolute">
      <parent link="Torso"/>
      <child link="RArm_rx"/>
      <origin rpy="0 0 0" xyz="0.1467 -0.0912 0.0579"/>
      <axis xyz="1 0 0"/>
      <limit effort="0" lower="-0.1" upper="0.3" velocity="1.0"/>
   </joint>
   <joint name="RArm_ry" type="revolute">
      <parent link="RArm_rx"/>
      <child link="RArm_ry"/>
      <origin rpy="0 0 0" xyz="0 0 0"/>
      <axis xyz="0 1 0"/>
      <limit effort="0" lower="-0.5" upper="0.2" velocity="1.0"/>
   </joint>
   <joint name="RArm_rz" type="revolute">
      <parent link="RArm_ry"/>
      <child link="RArm"/>
      <origin rpy="0 0 0" xyz="0 0 0"/>
      <axis xyz="0 0 1"/>
      <limit effort="0" lower="-0.2" upper="0.2" velocity="1.0"/>
   </joint>
  <joint name="RForearm_rx" type="fixed">
      <parent link="RArm"/>
      <child link="RForearm_rx"/>
      <origin rpy="0 0 0" xyz="-0.0022 -0.0239 -0.0724"/>
   </joint>
   <joint name="RForearm_ry" type="revolute">
      <parent link="RForearm_rx"/>
      <child link="RForearm_ry"/>
      <origin rpy="0 0 0" xyz="0 0 0"/>
      <axis xyz="0 1 0"/>
      <limit effort="0" lower="-0.6" upper="0.2" velocity="1.0"/>
   </joint>
   <joint name="RForearm_rz" type="fixed">
      <parent link="RForearm_ry"/>
      <child link="RForearm"/>
      <origin rpy="0 0 0" xyz="0 0 0"/>
   </joint>
  <joint name="RHand_rx" type="revolute">
      <parent link="RForearm"/>
      <child link="RHand_rx"/>
      <origin rpy="0 0 0" xyz="0.1128 0.0016 -0.1517"/>
      <axis xyz="1 0 0"/>
      <limit effort="0" lower="-0.2" upper="0.2" velocity="1.0"/>
   </joint>
   <joint name="RHand_ry" type="revolute">
      <parent link="RHand_rx"/>
      <child link="RHand_ry"/>
      <origin rpy="0 0 0" xyz="0 0 0"/>
      <axis xyz="0 1 0"/>
      <limit effort="0" lower="-0.1" upper="0.1" velocity="1.0"/>
   </joint>
   <joint name="RHand_rz" type="fixed">
      <parent link="RHand_ry"/>
      <child link="RHand"/>
      <origin rpy="0 0 0" xyz="0 0 0"/>
   </joint>
   <joint name="KangarooRHandSphere" type="fixed">
      <parent link="LHand"/>
      <child link="KangarooRHandSphere"/>
      <origin rpy="0 0 0" xyz="0 0 0"/>
   </joint>
</robot>
