<?xml version="1.0"?>
<robot name="RFootSphere">

   <link name="base_link"/>
   <joint name="base_link_J" type="fixed">
      <parent link="base_link"/>
      <child link="Pelvis"/>
      <origin rpy="0 0 0" xyz="0 0 0"/>
   </joint>

   <link name="Pelvis"/>

   <joint name="pelvis_rfoot_rom_joint" type="fixed">
      <parent link="Pelvis"/>
      <child link="pelvis_rfoot_rom"/>
      <origin rpy="0 0 0" xyz="0 0 0"/>
   </joint>

   <link name="pelvis_rfoot_rom">
      <visual>
         <origin xyz="0 0 0" rpy="0 0 0"/>
         <geometry>
            <mesh filename="package://hpp-rbprm-corba/meshes/skeleton/rfoot_rom.stl"/>
         </geometry>
      </visual>
      <collision>
         <origin xyz="0 0 0" rpy="0 0 0"/>
         <geometry>
            <mesh filename="package://hpp-rbprm-corba/meshes/skeleton/rfoot_rom.stl"/>
         </geometry>
      </collision>
   </link>

   <link name="PelvisSacrum_J1"/>
   <link name="PelvisSacrum_J2"/>
   <link name="Sacrum"/>
   <link name="SacrumL5_J1"/>
   <link name="SacrumL5_J2"/>
   <link name="L5"/>
   <link name="L5L4_J1"/>
   <link name="L5L4_J2"/>
   <link name="L4"/>
   <link name="L4L3_J1"/>
   <link name="L4L3_J2"/>
   <link name="L3"/>
   <link name="L3L2_J1"/>
   <link name="L3L2_J2"/>
   <link name="L2"/>
   <link name="L2L1_J1"/>
   <link name="L2L1_J2"/>
   <link name="L1"/>
   <link name="L1Thorax_J1"/>
   <link name="L1Thorax_J2"/>
   <link name="Thorax"/>
   <link name="ThoraxSkull_J1"/>
   <link name="ThoraxSkull_J2"/>
   <link name="Skull"/>

   <joint name="PelvisSacrum_J1" type="revolute">
      <parent link="Pelvis"/>
      <child link="PelvisSacrum_J1"/>
      <origin rpy="0 0 0" xyz="-0.010389 0 0.018889"/>
      <axis xyz="1 0 0"/>
      <limit effort="0" lower="-0.2" upper="0.2" velocity="1.0"/>
   </joint>
   <joint name="PelvisSacrum_J2" type="revolute">
      <parent link="PelvisSacrum_J1"/>
      <child link="PelvisSacrum_J2"/>
      <origin rpy="0 0 0" xyz="0 0 0"/>
      <axis xyz="0 0 1"/>
      <limit effort="0" lower="-0.2" upper="0.2" velocity="1.0"/>
   </joint>
   <joint name="Sacrum" type="revolute">
      <parent link="PelvisSacrum_J2"/>
      <child link="Sacrum"/>
      <origin rpy="0 0 0" xyz="0 0 0"/>
      <axis xyz="0 1 0"/>
      <limit effort="0" lower="-0.1" upper="0.3" velocity="1.0"/>
   </joint>
   <joint name="SacrumL5_J1" type="revolute">
      <parent link="Sacrum"/>
      <child link="SacrumL5_J1"/>
      <origin rpy="0 0 0" xyz="0.015111 0 0.023611"/>
      <axis xyz="1 0 0"/>
      <limit effort="0" lower="-0.1" upper="0.1" velocity="1.0"/>
   </joint>
   <joint name="SacrumL5_J2" type="revolute">
      <parent link="SacrumL5_J1"/>
      <child link="SacrumL5_J2"/>
      <origin rpy="0 0 0" xyz="0 0 0"/>
      <axis xyz="0 0 1"/>
      <limit effort="0" lower="-0.1" upper="0.1" velocity="1.0"/>
   </joint>
   <joint name="L5" type="revolute">
      <parent link="SacrumL5_J2"/>
      <child link="L5"/>
      <origin rpy="0 0 0" xyz="0 0 0"/>
      <axis xyz="0 1 0"/>
      <limit effort="0" lower="-0.1" upper="0.1" velocity="1.0"/>
   </joint>
   <joint name="L5L4_J1" type="revolute">
      <parent link="L5"/>
      <child link="L5L4_J1"/>
      <origin rpy="0 0 0" xyz="0.0066111 0 0.030222"/>
      <axis xyz="1 0 0"/>
      <limit effort="0" lower="-0.1" upper="0.1" velocity="1.0"/>
   </joint>
   <joint name="L5L4_J2" type="revolute">
      <parent link="L5L4_J1"/>
      <child link="L5L4_J2"/>
      <origin rpy="0 0 0" xyz="0 0 0"/>
      <axis xyz="0 0 1"/>
      <limit effort="0" lower="-0.1" upper="0.1" velocity="1.0"/>
   </joint>
   <joint name="L4" type="revolute">
      <parent link="L5L4_J2"/>
      <child link="L4"/>
      <origin rpy="0 0 0" xyz="0 0 0"/>
      <axis xyz="0 1 0"/>
      <limit effort="0" lower="-0.1" upper="0.1" velocity="1.0"/>
   </joint>
   <joint name="L4L3_J1" type="revolute">
      <parent link="L4"/>
      <child link="L4L3_J1"/>
      <origin rpy="0 0 0" xyz="0 0 0.032111"/>
      <axis xyz="1 0 0"/>
      <limit effort="0" lower="-0.1" upper="0.1" velocity="1.0"/>
   </joint>
   <joint name="L4L3_J2" type="revolute">
      <parent link="L4L3_J1"/>
      <child link="L4L3_J2"/>
      <origin rpy="0 0 0" xyz="0 0 0"/>
      <axis xyz="0 0 1"/>
      <limit effort="0" lower="-0.1" upper="0.1" velocity="1.0"/>
   </joint>
   <joint name="L3" type="revolute">
      <parent link="L4L3_J2"/>
      <child link="L3"/>
      <origin rpy="0 0 0" xyz="0 0 0"/>
      <axis xyz="0 1 0"/>
      <limit effort="0" lower="-0.1" upper="0.1" velocity="1.0"/>
   </joint>
   <joint name="L3L2_J1" type="revolute">
      <parent link="L3"/>
      <child link="L3L2_J1"/>
      <origin rpy="0 0 0" xyz="-0.0056667 0 0.031167"/>
      <axis xyz="1 0 0"/>
      <limit effort="0" lower="-0.1" upper="0.1" velocity="1.0"/>
   </joint>
   <joint name="L3L2_J2" type="revolute">
      <parent link="L3L2_J1"/>
      <child link="L3L2_J2"/>
      <origin rpy="0 0 0" xyz="0 0 0"/>
      <axis xyz="0 0 1"/>
      <limit effort="0" lower="-0.1" upper="0.1" velocity="1.0"/>
   </joint>
   <joint name="L2" type="revolute">
      <parent link="L3L2_J2"/>
      <child link="L2"/>
      <origin rpy="0 0 0" xyz="0 0 0"/>
      <axis xyz="0 1 0"/>
      <limit effort="0" lower="-0.1" upper="0.1" velocity="1.0"/>
   </joint>
   <joint name="L2L1_J1" type="revolute">
      <parent link="L2"/>
      <child link="L2L1_J1"/>
      <origin rpy="0 0 0" xyz="-0.0094444 0 0.027389"/>
      <axis xyz="1 0 0"/>
      <limit effort="0" lower="-0.1" upper="0.1" velocity="1.0"/>
   </joint>
   <joint name="L2L1_J2" type="revolute">
      <parent link="L2L1_J1"/>
      <child link="L2L1_J2"/>
      <origin rpy="0 0 0" xyz="0 0 0"/>
      <axis xyz="0 0 1"/>
      <limit effort="0" lower="-0.1" upper="0.1" velocity="1.0"/>
   </joint>
   <joint name="L1" type="revolute">
      <parent link="L2L1_J2"/>
      <child link="L1"/>
      <origin rpy="0 0 0" xyz="0 0 0"/>
      <axis xyz="0 1 0"/>
      <limit effort="0" lower="-0.1" upper="0.1" velocity="1.0"/>
   </joint>
   <joint name="L1Thorax_J1" type="revolute">
      <parent link="L1"/>
      <child link="L1Thorax_J1"/>
      <origin rpy="0 0 0" xyz="-0.011333 0 0.029278"/>
      <axis xyz="1 0 0"/>
      <limit effort="0" lower="-0.2" upper="0.2" velocity="1.0"/>
   </joint>
   <joint name="L1Thorax_J2" type="revolute">
      <parent link="L1Thorax_J1"/>
      <child link="L1Thorax_J2"/>
      <origin rpy="0 0 0" xyz="0 0 0"/>
      <axis xyz="0 0 1"/>
      <limit effort="0" lower="-1.5" upper="1.5" velocity="1.0"/>
   </joint>
   <joint name="Thorax" type="revolute">
      <parent link="L1Thorax_J2"/>
      <child link="Thorax"/>
      <origin rpy="0 0 0" xyz="0 0 0"/>
      <axis xyz="0 1 0"/>
      <limit effort="0" lower="-0.5" upper="0.6" velocity="1.0"/>
   </joint>
   <joint name="ThoraxSkull_J1" type="revolute">
      <parent link="Thorax"/>
      <child link="ThoraxSkull_J1"/>
      <origin rpy="0 0 0" xyz="0.0037778 0 0.42122"/>
      <axis xyz="1 0 0"/>
      <limit effort="0" lower="-0.3" upper="0.3" velocity="1.0"/>
   </joint>
   <joint name="ThoraxSkull_J2" type="revolute">
      <parent link="ThoraxSkull_J1"/>
      <child link="ThoraxSkull_J2"/>
      <origin rpy="0 0 0" xyz="0 0 0"/>
      <axis xyz="0 0 1"/>
      <limit effort="0" lower="-1.4" upper="1.4" velocity="1.0"/>
   </joint>
   <joint name="Skull" type="revolute">
      <parent link="ThoraxSkull_J2"/>
      <child link="Skull"/>
      <origin rpy="0 0 0" xyz="0 0 0"/>
      <axis xyz="0 1 0"/>
      <limit effort="0" lower="-1.1" upper="0.4" velocity="1.0"/>
   </joint>
</robot>
