<?xml version="1.0"?>
<robot name="skeleton">
  <material name="Blue"> <!-- for spheres -->
    <color rgba="0 0 1 0.5"/>
  </material>
  <material name="White"> <!-- for bones -->
    <color rgba="1 1 1 1"/>
  </material>
  <material name="Green"> <!-- for bones -->
    <color rgba="0 1 0.1 0.2"/>
  </material>

  <link name="base_link"/>
  <joint name="base_link_J" type="fixed">
      <parent link="base_link"/>
      <child link="Pelvis"/>
      <origin rpy="0 0 0" xyz="0 0 0"/>
   </joint>

   <link name="Pelvis">
      <inertial>
         <origin rpy="0 0 0" xyz="0 0 0"/>
         <mass value="8.4552"/>
         <inertia ixx="0" ixy="0" ixz="0" iyy="0" iyz="0" izz="0"/>
      </inertial>
      <visual>
         <origin xyz="0 0 0" rpy="0 0 0"/>
         <geometry>
            <mesh filename="package://hpp-rbprm-corba/meshes/skeleton/Pelvis.stl"/>
         </geometry>
         <material name="White"/>
      </visual>
      <collision>
         <origin xyz="0 0 0" rpy="0 0 0"/>
         <geometry>
            <mesh filename="package://hpp-rbprm-corba/meshes/skeleton/Pelvis.stl"/>
         </geometry>
      </collision>
   </link>

 <!--<joint name="pelvis_rfoot_rom_joint" type="fixed">
      <parent link="Pelvis"/>
      <child link="pelvis_rfoot_rom"/>
      <origin rpy="0 0 0" xyz="0 0 0"/>
   </joint>

  <link name="pelvis_rfoot_rom">
      <visual>
         <origin xyz="0 0 0" rpy="0 0 0"/>
         <geometry>
            <mesh filename="package://hpp-rbprm-corba/meshes/skeleton/rfoot_rom.stl"/>
         </geometry>
         <material name="Green"/>
      </visual>
   </link>-->

  <!--<joint name="pelvis_lfoot_rom_joint" type="fixed">
      <parent link="Pelvis"/>
      <child link="pelvis_lfoot_rom"/>
      <origin rpy="0 0 0" xyz="0 0 0"/>
   </joint>

  <link name="pelvis_lfoot_rom">
      <visual>
         <origin xyz="0 0 0" rpy="0 0 0"/>
         <geometry>
            <mesh filename="package://hpp-rbprm-corba/meshes/skeleton/lfoot_rom.stl"/>
         </geometry>
         <material name="Green"/>
      </visual>
   </link>-->


   <link name="PelvisSacrum_J1"/>
   <link name="PelvisSacrum_J2"/>
   <link name="Sacrum">
      <inertial>
         <origin rpy="0 0 0" xyz="-0.0255 0 0.028333"/>
         <mass value="0"/>
         <inertia ixx="0" ixy="0" ixz="0" iyy="0" iyz="0" izz="0"/>
      </inertial>
      <visual>
         <origin xyz="-0.0255 0 0.028333" rpy="0 0 0"/>
         <geometry>
            <mesh filename="package://hpp-rbprm-corba/meshes/skeleton/Sacrum.stl"/>
         </geometry>
         <material name="White"/>
      </visual>
      <collision>
         <origin xyz="-0.0255 0.028333 0" rpy="0 0 0"/>
         <geometry>
            <mesh filename="package://hpp-rbprm-corba/meshes/skeleton/Sacrum.stl"/>
         </geometry>
      </collision>
   </link>
   <link name="SacrumL5_J1"/>
   <link name="SacrumL5_J2"/>
   <link name="L5">
      <inertial>
         <origin rpy="0 0 0" xyz="0.0075556 0 0.013222"/>
         <mass value="0"/>
         <inertia ixx="0" ixy="0" ixz="0" iyy="0" iyz="0" izz="0"/>
      </inertial>
      <visual>
         <origin xyz="0.0075556 0 0.013222" rpy="0 0 0"/>
         <geometry>
            <mesh filename="package://hpp-rbprm-corba/meshes/skeleton/L5.stl"/>
         </geometry>
         <material name="White"/>
      </visual>
      <collision>
         <origin xyz="0.0075556 0 0.013222" rpy="0 0 0"/>
         <geometry>
            <mesh filename="package://hpp-rbprm-corba/meshes/skeleton/L5.stl"/>
         </geometry>
      </collision>
   </link>
   <link name="L5L4_J1"/>
   <link name="L5L4_J2"/>
   <link name="L4">
      <inertial>
         <origin rpy="0 0 0" xyz="0.0056667 0 0.016056"/>
         <mass value="0"/>
         <inertia ixx="0" ixy="0" ixz="0" iyy="0" iyz="0" izz="0"/>
      </inertial>
      <visual>
         <origin xyz="0.0056667 0 0.016056" rpy="0 0 0"/>
         <geometry>
            <mesh filename="package://hpp-rbprm-corba/meshes/skeleton/L4.stl"/>
         </geometry>
         <material name="White"/>
      </visual>
      <collision>
         <origin xyz="0.0056667 0 0.016056" rpy="0 0 0"/>
         <geometry>
            <mesh filename="package://hpp-rbprm-corba/meshes/skeleton/L4.stl"/>
         </geometry>
      </collision>
   </link>
   <link name="L4L3_J1"/>
   <link name="L4L3_J2"/>
   <link name="L3">
      <inertial>
         <origin rpy="0 0 0" xyz="0.00094444 0 0.017"/>
         <mass value="0"/>
         <inertia ixx="0" ixy="0" ixz="0" iyy="0" iyz="0" izz="0"/>
      </inertial>
      <visual>
         <origin xyz="0.00094444 0 0.017" rpy="0 0 0"/>
         <geometry>
            <mesh filename="package://hpp-rbprm-corba/meshes/skeleton/L3.stl"/>
         </geometry>
         <material name="White"/>
      </visual>
      <collision>
         <origin xyz="0.00094444 0 0.017" rpy="0 0 0"/>
         <geometry>
            <mesh filename="package://hpp-rbprm-corba/meshes/skeleton/L3.stl"/>
         </geometry>
      </collision>
   </link>
   <link name="L3L2_J1"/>
   <link name="L3L2_J2"/>
   <link name="L2">
      <inertial>
         <origin rpy="0 0 0" xyz="-0.00094444 0 0.015111"/>
         <mass value="0"/>
         <inertia ixx="0" ixy="0" ixz="0" iyy="0" iyz="0" izz="0"/>
      </inertial>
      <visual>
         <origin xyz="-0.00094444 0 0.015111" rpy="0 0 0"/>
         <geometry>
            <mesh filename="package://hpp-rbprm-corba/meshes/skeleton/L2.stl"/>
         </geometry>
         <material name="White"/>
      </visual>
      <collision>
         <origin xyz="-0.00094444 0 0.015111" rpy="0 0 0"/>
         <geometry>
            <mesh filename="package://hpp-rbprm-corba/meshes/skeleton/L2.stl"/>
         </geometry>
      </collision>
   </link>
   <link name="L2L1_J1"/>
   <link name="L2L1_J2"/>
   <link name="L1">
      <inertial>
         <origin rpy="0 0 0" xyz="-0.0028333 0 0.015111"/>
         <mass value="0"/>
         <inertia ixx="0" ixy="0" ixz="0" iyy="0" iyz="0" izz="0"/>
      </inertial>
      <visual>
         <origin xyz="-0.0028333 0 0.015111" rpy="0 0 0"/>
         <geometry>
            <mesh filename="package://hpp-rbprm-corba/meshes/skeleton/L1.stl"/>
         </geometry>
         <material name="White"/>
      </visual>
      <collision>
         <origin xyz="-0.0028333 0 0.015111" rpy="0 0 0"/>
         <geometry>
            <mesh filename="package://hpp-rbprm-corba/meshes/skeleton/L1.stl"/>
         </geometry>
      </collision>
   </link>
   <link name="L1Thorax_J1"/>
   <link name="L1Thorax_J2"/>
   <link name="Thorax">
      <inertial>
         <origin rpy="0 0 0" xyz="0.035889 0 0.14072"/>
         <mass value="19.8372"/>
         <inertia ixx="-0.16485" ixy="0.25777" ixz="0.0015499" iyy="0.20309" iyz="-0.0061998" izz="-0.18263"/>
      </inertial>
      <visual>
         <origin xyz="0.035889 0 0.14072" rpy="0 0 0"/>
         <geometry>
            <mesh filename="package://hpp-rbprm-corba/meshes/skeleton/Thorax.stl"/>
         </geometry>
         <material name="White"/>
      </visual>
      <collision>
         <origin xyz="0.035889 0 0.14072" rpy="0 0 0"/>
         <geometry>
            <mesh filename="package://hpp-rbprm-corba/meshes/skeleton/Thorax.stl"/>
         </geometry>
      </collision>
   </link>

  <!--<joint name="thorax_rhand_rom_joint" type="fixed">
      <parent link="Thorax"/>
      <child link="thorax_rhand_rom"/>
      <origin rpy="0 0 0" xyz="0 0 0"/>
   </joint>

  <link name="thorax_rhand_rom">
      <visual>
         <origin xyz="0 0 0" rpy="0 0 0"/>
         <geometry>
            <mesh filename="package://hpp-rbprm-corba/meshes/skeleton/rhand_rom.stl"/>
         </geometry>
         <material name="Green"/>
      </visual>
   </link>-->

  <!--<joint name="thorax_lhand_rom_joint" type="fixed">
      <parent link="Thorax"/>
      <child link="thorax_lhand_rom"/>
      <origin rpy="0 0 0" xyz="0 0 0"/>
   </joint>

  <link name="thorax_lhand_rom">
      <visual>
         <origin xyz="0 0 0" rpy="0 0 0"/>
         <geometry>
            <mesh filename="package://hpp-rbprm-corba/meshes/skeleton/lhand_rom.stl"/>
         </geometry>
         <material name="Green"/>
      </visual>
   </link>-->

   <link name="ThoraxSkull_J1"/>
   <link name="ThoraxSkull_J2"/>
   <link name="Skull">
      <inertial>
         <origin rpy="0 0 0" xyz="0 0 0"/>
         <mass value="4.2276"/>
         <inertia ixx="0.0071027" ixy="-0.00059867" ixz="-2.9564e-05" iyy="0.0046194" iyz="6.6519e-05" izz="0.0080488"/>
      </inertial>
      <visual>
         <origin xyz="0 0 0" rpy="0 0 0"/>
         <geometry>
            <mesh filename="package://hpp-rbprm-corba/meshes/skeleton/Skull.stl"/>
         </geometry>
         <material name="White"/>
      </visual>
      <collision>
         <origin xyz="0 0 0" rpy="0 0 0"/>
         <geometry>
            <mesh filename="package://hpp-rbprm-corba/meshes/skeleton/Skull.stl"/>
         </geometry>
      </collision>
   </link>
   <link name="RHip_J1"/>
   <link name="RHip_J2"/>
   <link name="RThigh">
      <inertial>
         <origin rpy="0 0 0" xyz="0 -0.035889 -0.18606"/>
         <mass value="7.3797"/>
         <inertia ixx="0.11501" ixy="0.0067008" ixz="-0.000547" iyy="0.030769" iyz="-0.0067008" izz="0.12308"/>
      </inertial>
      <visual>
         <origin xyz="0 -0.035889 -0.18606" rpy="0 0 0"/>
         <geometry>
            <mesh filename="package://hpp-rbprm-corba/meshes/skeleton/RThigh.stl"/>
         </geometry>
         <material name="White"/>
      </visual>
      <collision>
         <origin xyz="0 -0.035889 -0.18606" rpy="0 0 0"/>
         <geometry>
            <mesh filename="package://hpp-rbprm-corba/meshes/skeleton/RThigh.stl"/>
         </geometry>
      </collision>
   </link>
   <link name="RShank">
      <inertial>
         <origin rpy="0 0 0" xyz="0 0 -0.18813"/>
         <mass value="2.8801"/>
         <inertia ixx="0.042617" ixy="-0.00086974" ixz="-0.00021743" iyy="0.0054359" iyz="0.001359" izz="0.042617"/>
      </inertial>
      <visual>
         <origin xyz="0 0 -0.18813" rpy="0 0 0"/>
         <geometry>
            <mesh filename="package://hpp-rbprm-corba/meshes/skeleton/RShank.stl"/>
         </geometry>
         <material name="White"/>
      </visual>
      <collision>
         <origin xyz="0 0 -0.18813" rpy="0 0 0"/>
         <geometry>
            <mesh filename="package://hpp-rbprm-corba/meshes/skeleton/RShank.stl"/>
         </geometry>
      </collision>
   </link>
   <link name="RAnkle_J1">
   </link>
   <link name="RFoot">
      <inertial>
         <origin rpy="0 0 0" xyz="0.065875 -0.018889 -0.025972"/>
         <mass value="0.72029"/>
         <inertia ixx="0.0035454" ixy="0.00043767" ixz="0" iyy="0.00074844" iyz="-0.00016575" izz="0.0033563"/>
      </inertial>
      <visual>
         <origin xyz="0.065875 -0.018889 -0.025972" rpy="0 0 0"/>
         <geometry>
            <mesh filename="package://hpp-rbprm-corba/meshes/skeleton/RFoot.stl"/>
         </geometry>
         <material name="White"/>
      </visual>
      <collision>
         <origin xyz="0.065875 -0.018889 -0.025972" rpy="0 0 0"/>
         <geometry>
            <mesh filename="package://hpp-rbprm-corba/meshes/skeleton/RFoot.stl"/>
         </geometry>
      </collision>
   </link>
   <link name="RFootToe">
      <inertial>
         <origin rpy="0 0 0" xyz="0 0 0"/>
         <mass value="0.2"/>
         <inertia ixx="0.0035454" ixy="0.00043767" ixz="0" iyy="0.00074844" iyz="-0.00016575" izz="0.0033563"/>
      </inertial>
      <visual>
         <origin xyz="0 0 0" rpy="0 0 0"/>
         <geometry>
            <mesh filename="package://hpp-rbprm-corba/meshes/skeleton/RFootToe.stl"/>
         </geometry>
         <material name="White"/>
      </visual>
      <collision>
         <origin xyz="0 0 0" rpy="0 0 0"/>
         <geometry>
            <mesh filename="package://hpp-rbprm-corba/meshes/skeleton/RFootToe.stl"/>
         </geometry>
      </collision>
   </link>
  <link name="RFootSphere">
      <visual>
         <origin xyz="0 0 0" rpy="0 0 0"/>
         <geometry>
            <sphere radius="0.01"/>
         </geometry>
         <material name="Blue"/>
      </visual>
   </link>
   <link name="LHip_J1">
   </link>
   <link name="LHip_J2">
   </link>
   <link name="LThigh">
      <inertial>
         <origin rpy="0 0 0" xyz="0 0.035889 -0.18606"/>
         <mass value="7.3797"/>
         <inertia ixx="0.11501" ixy="0.0067008" ixz="-0.000547" iyy="0.030769" iyz="-0.0067008" izz="0.12308"/>
      </inertial>
      <visual>
         <origin xyz="0 0.035889 -0.18606" rpy="0 0 0"/>
         <geometry>
            <mesh filename="package://hpp-rbprm-corba/meshes/skeleton/LThigh.stl"/>
         </geometry>
         <material name="White"/>
      </visual>
      <collision>
         <origin xyz="0 0.035889 -0.18606" rpy="0 0 0"/>
         <geometry>
            <mesh filename="package://hpp-rbprm-corba/meshes/skeleton/LThigh.stl"/>
         </geometry>
      </collision>
   </link>
   <link name="LShank">
      <inertial>
         <origin rpy="0 0 0" xyz="0 0 -0.18813"/>
         <mass value="2.8801"/>
         <inertia ixx="0.042617" ixy="-0.00086974" ixz="-0.00021743" iyy="0.0054359" iyz="0.001359" izz="0.042617"/>
      </inertial>
      <visual>
         <origin xyz="0 0 -0.18813" rpy="0 0 0"/>
         <geometry>
            <mesh filename="package://hpp-rbprm-corba/meshes/skeleton/LShank.stl"/>
         </geometry>
         <material name="White"/>
      </visual>
      <collision>
         <origin xyz="0 0 -0.18813" rpy="0 0 0"/>
         <geometry>
            <mesh filename="package://hpp-rbprm-corba/meshes/skeleton/LShank.stl"/>
         </geometry>
      </collision>
   </link>
   <link name="LAnkle_J1">
   </link>
   <link name="LFoot">
      <inertial>
         <origin rpy="0 0 0" xyz="0.065875 0.018889 -0.025972"/>
         <mass value="0.72029"/>
         <inertia ixx="0.0035454" ixy="0.00043767" ixz="0" iyy="0.00074844" iyz="-0.00016575" izz="0.0033563"/>
      </inertial>
      <visual>
         <origin xyz="0.065875 0.018889 -0.025972" rpy="0 0 0"/>
         <geometry>
            <mesh filename="package://hpp-rbprm-corba/meshes/skeleton/LFoot.stl"/>
         </geometry>
         <material name="White"/>
      </visual>
      <collision>
         <origin xyz="0.065875 0.018889 -0.025972" rpy="0 0 0"/>
         <geometry>
            <mesh filename="package://hpp-rbprm-corba/meshes/skeleton/LFoot.stl"/>
         </geometry>
      </collision>
   </link>
   <link name="LFootToe">
      <inertial>
         <origin rpy="0 0 0" xyz="0 0 0"/>
         <mass value="0.2"/>
         <inertia ixx="0.0035454" ixy="0.00043767" ixz="0" iyy="0.00074844" iyz="-0.00016575" izz="0.0033563"/>
      </inertial>
      <visual>
         <origin xyz="0 0 0" rpy="0 0 0"/>
         <geometry>
            <mesh filename="package://hpp-rbprm-corba/meshes/skeleton/LFootToe.stl"/>
         </geometry>
         <material name="White"/>
      </visual>
      <collision>
         <origin xyz="0 0 0" rpy="0 0 0"/>
         <geometry>
            <mesh filename="package://hpp-rbprm-corba/meshes/skeleton/LFootToe.stl"/>
         </geometry>
      </collision>
   </link>
  <link name="LFootSphere">
      <visual>
         <origin xyz="0 0 0" rpy="0 0 0"/>
         <geometry>
            <sphere radius="0.01"/>
         </geometry>
         <material name="Blue"/>
      </visual>
   </link>
   <link name="RShoulder_J1"/>
   <link name="RShoulder_J2"/>
   <link name="RHumerus">
      <inertial>
         <origin rpy="0 0 0" xyz="0 0 -0.1581"/>
         <mass value="1.4399"/>
         <inertia ixx="-0.022156" ixy="0.00051827" ixz="0.00035991" iyy="0.0028217" iyz="5.7586e-05" izz="-0.021249"/>
      </inertial>
      <visual>
         <origin xyz="0 0 -0.1581" rpy="0 0 0"/>
         <geometry>
            <mesh filename="package://hpp-rbprm-corba/meshes/skeleton/RHumerus.stl"/>
         </geometry>
         <material name="White"/>
      </visual>
      <collision>
         <origin xyz="0 0 -0.1581" rpy="0 0 0"/>
         <geometry>
            <mesh filename="package://hpp-rbprm-corba/meshes/skeleton/RHumerus.stl"/>
         </geometry>
      </collision>
   </link>
   <link name="RElbow_J1"/>
   <link name="RForearm">
      <inertial>
         <origin rpy="0 0 0" xyz="0 0 -0.11352"/>
         <mass value="1.02"/>
         <inertia ixx="-0.0082187" ixy="5.6551e-05" ixz="2.5134e-05" iyy="0.0007603" iyz="-0.00040214" izz="-0.0085643"/>
      </inertial>
      <visual>
         <origin xyz="0 0 -0.11352" rpy="0 0 0"/>
         <geometry>
            <mesh filename="package://hpp-rbprm-corba/meshes/skeleton/RForearm.stl"/>
         </geometry>
         <material name="White"/>
      </visual>
      <collision>
         <origin xyz="0 0 -0.11352" rpy="0 0 0"/>
         <geometry>
            <mesh filename="package://hpp-rbprm-corba/meshes/skeleton/RForearm.stl"/>
         </geometry>
      </collision>
   </link>
   <link name="RWrist_J1"/>
   <link name="RHand">
      <inertial>
         <origin rpy="0 0 0" xyz="0 0 -0.049867"/>
         <mass value="0.36011"/>
         <inertia ixx="0.0036215" ixy="0.00058753" ixz="0.00027313" iyy="0.0017529" iyz="-0.00048556" izz="0.0029113"/>
      </inertial>
      <visual>
         <origin xyz="0 0 -0.049867" rpy="0 0 0"/>
         <geometry>
            <mesh filename="package://hpp-rbprm-corba/meshes/skeleton/RHand.stl"/>
         </geometry>
         <material name="White"/>
      </visual>
      <collision>
         <origin xyz="0 0 -0.049867" rpy="0 0 0"/>
         <geometry>
            <mesh filename="package://hpp-rbprm-corba/meshes/skeleton/RHand.stl"/>
         </geometry>
      </collision>
   </link>
  <link name="RHandSphere">
      <visual>
         <origin xyz="0 0 0" rpy="0 0 0"/>
         <geometry>
            <sphere radius = "0.01"/>
         </geometry>
         <material name="Blue"/>
      </visual>
   </link>

   <link name="LShoulder_J1"/>
   <link name="LShoulder_J2"/>
   <link name="LHumerus">
      <inertial>
         <origin rpy="0 0 0" xyz="0 0 -0.1581"/>
         <mass value="1.4399"/>
         <inertia ixx="-0.022156" ixy="0.00051827" ixz="0.00035991" iyy="0.0028217" iyz="5.7586e-05" izz="-0.021249"/>
      </inertial>
      <visual>
         <origin xyz="0 0 -0.1581" rpy="0 0 0"/>
         <geometry>
            <mesh filename="package://hpp-rbprm-corba/meshes/skeleton/LHumerus.stl"/>
         </geometry>
         <material name="White"/>
      </visual>
      <collision>
         <origin xyz="0 0 -0.1581" rpy="0 0 0"/>
         <geometry>
            <mesh filename="package://hpp-rbprm-corba/meshes/skeleton/LHumerus.stl"/>
         </geometry>
      </collision>
   </link>
   <link name="LElbow_J1"/>
   <link name="LForearm">
      <inertial>
         <origin rpy="0 0 0" xyz="0 -0.11352 0"/>
         <mass value="1.02"/>
         <inertia ixx="-0.0082187" ixy="5.6551e-05" ixz="2.5134e-05" iyy="0.0007603" iyz="-0.00040214" izz="-0.0085643"/>
      </inertial>
      <visual>
         <origin xyz="0 0 -0.11352" rpy="0 0 0"/>
         <geometry>
            <mesh filename="package://hpp-rbprm-corba/meshes/skeleton/LForearm.stl"/>
         </geometry>
         <material name="White"/>
      </visual>
      <collision>
         <origin xyz="0 0 -0.11352" rpy="0 0 0"/>
         <geometry>
            <mesh filename="package://hpp-rbprm-corba/meshes/skeleton/LForearm.stl"/>
         </geometry>
      </collision>
   </link>
   <link name="LWrist_J1"/>
   <link name="LHand">
      <inertial>
         <origin rpy="0 0 0" xyz="0  0 -0.049867"/>
         <mass value="0.36011"/>
         <inertia ixx="0.0036215" ixy="0.00058753" ixz="0.00027313" iyy="0.0017529" iyz="-0.00048556" izz="0.0029113"/>
      </inertial>
      <visual>
         <origin xyz="0  0 -0.049867" rpy="0 0 0"/>
         <geometry>
            <mesh filename="package://hpp-rbprm-corba/meshes/skeleton/LHand.stl"/>
         </geometry>
         <material name="White"/>
      </visual>
      <collision>
         <origin xyz="0 0 -0.049867" rpy="0 0 0"/>
         <geometry>
            <mesh filename="package://hpp-rbprm-corba/meshes/skeleton/LHand.stl"/>
         </geometry>
      </collision>
   </link>
  <link name="LHandSphere">
      <visual>
         <origin xyz="0 0 0" rpy="0 0 0"/>
         <geometry>
            <sphere radius="0.01"/>
         </geometry>
         <material name="Blue"/>
      </visual>
   </link>

   <joint name="A_PelvisSacrum_J1" type="revolute"> <!-- A_ added for order while parsing with ROS -->
      <parent link="Pelvis"/>
      <child link="PelvisSacrum_J1"/>
      <origin rpy="0 0 0" xyz="-0.010389 0 0.018889"/>
      <axis xyz="1 0 0"/>
      <limit effort="0" lower="-0.2" upper="0.2" velocity="1.0"/>
   </joint>
   <joint name="PelvisSacrum_J2" type="revolute">
      <parent link="PelvisSacrum_J1"/>
      <child link="PelvisSacrum_J2"/>
      <origin rpy="0 0 0" xyz="0 0 0"/>
      <axis xyz="0 0 1"/>
      <limit effort="0" lower="-0.2" upper="0.2" velocity="1.0"/>
   </joint>
   <joint name="Sacrum" type="revolute">
      <parent link="PelvisSacrum_J2"/>
      <child link="Sacrum"/>
      <origin rpy="0 0 0" xyz="0 0 0"/>
      <axis xyz="0 1 0"/>
      <limit effort="0" lower="-0.1" upper="0.3" velocity="1.0"/>
   </joint>
   <joint name="SacrumL5_J1" type="revolute">
      <parent link="Sacrum"/>
      <child link="SacrumL5_J1"/>
      <origin rpy="0 0 0" xyz="0.015111 0 0.023611"/>
      <axis xyz="1 0 0"/>
      <limit effort="0" lower="-0.1" upper="0.1" velocity="1.0"/>
   </joint>
   <joint name="SacrumL5_J2" type="revolute">
      <parent link="SacrumL5_J1"/>
      <child link="SacrumL5_J2"/>
      <origin rpy="0 0 0" xyz="0 0 0"/>
      <axis xyz="0 0 1"/>
      <limit effort="0" lower="-0.1" upper="0.1" velocity="1.0"/>
   </joint>
   <joint name="L5" type="revolute">
      <parent link="SacrumL5_J2"/>
      <child link="L5"/>
      <origin rpy="0 0 0" xyz="0 0 0"/>
      <axis xyz="0 1 0"/>
      <limit effort="0" lower="-0.1" upper="0.1" velocity="1.0"/>
   </joint>
   <joint name="L5L4_J1" type="revolute">
      <parent link="L5"/>
      <child link="L5L4_J1"/>
      <origin rpy="0 0 0" xyz="0.0066111 0 0.030222"/>
      <axis xyz="1 0 0"/>
      <limit effort="0" lower="-0.1" upper="0.1" velocity="1.0"/>
   </joint>
   <joint name="L5L4_J2" type="revolute">
      <parent link="L5L4_J1"/>
      <child link="L5L4_J2"/>
      <origin rpy="0 0 0" xyz="0 0 0"/>
      <axis xyz="0 0 1"/>
      <limit effort="0" lower="-0.1" upper="0.1" velocity="1.0"/>
   </joint>
   <joint name="L4" type="revolute">
      <parent link="L5L4_J2"/>
      <child link="L4"/>
      <origin rpy="0 0 0" xyz="0 0 0"/>
      <axis xyz="0 1 0"/>
      <limit effort="0" lower="-0.1" upper="0.1" velocity="1.0"/>
   </joint>
   <joint name="L4L3_J1" type="revolute">
      <parent link="L4"/>
      <child link="L4L3_J1"/>
      <origin rpy="0 0 0" xyz="0 0 0.032111"/>
      <axis xyz="1 0 0"/>
      <limit effort="0" lower="-0.1" upper="0.1" velocity="1.0"/>
   </joint>
   <joint name="L4L3_J2" type="revolute">
      <parent link="L4L3_J1"/>
      <child link="L4L3_J2"/>
      <origin rpy="0 0 0" xyz="0 0 0"/>
      <axis xyz="0 0 1"/>
      <limit effort="0" lower="-0.1" upper="0.1" velocity="1.0"/>
   </joint>
   <joint name="L3" type="revolute">
      <parent link="L4L3_J2"/>
      <child link="L3"/>
      <origin rpy="0 0 0" xyz="0 0 0"/>
      <axis xyz="0 1 0"/>
      <limit effort="0" lower="-0.1" upper="0.1" velocity="1.0"/>
   </joint>
   <joint name="L3L2_J1" type="revolute">
      <parent link="L3"/>
      <child link="L3L2_J1"/>
      <origin rpy="0 0 0" xyz="-0.0056667 0 0.031167"/>
      <axis xyz="1 0 0"/>
      <limit effort="0" lower="-0.1" upper="0.1" velocity="1.0"/>
   </joint>
   <joint name="L3L2_J2" type="revolute">
      <parent link="L3L2_J1"/>
      <child link="L3L2_J2"/>
      <origin rpy="0 0 0" xyz="0 0 0"/>
      <axis xyz="0 0 1"/>
      <limit effort="0" lower="-0.1" upper="0.1" velocity="1.0"/>
   </joint>
   <joint name="L2" type="revolute">
      <parent link="L3L2_J2"/>
      <child link="L2"/>
      <origin rpy="0 0 0" xyz="0 0 0"/>
      <axis xyz="0 1 0"/>
      <limit effort="0" lower="-0.1" upper="0.1" velocity="1.0"/>
   </joint>
   <joint name="L2L1_J1" type="revolute">
      <parent link="L2"/>
      <child link="L2L1_J1"/>
      <origin rpy="0 0 0" xyz="-0.0094444 0 0.027389"/>
      <axis xyz="1 0 0"/>
      <limit effort="0" lower="-0.1" upper="0.1" velocity="1.0"/>
   </joint>
   <joint name="L2L1_J2" type="revolute">
      <parent link="L2L1_J1"/>
      <child link="L2L1_J2"/>
      <origin rpy="0 0 0" xyz="0 0 0"/>
      <axis xyz="0 0 1"/>
      <limit effort="0" lower="-0.1" upper="0.1" velocity="1.0"/>
   </joint>
   <joint name="L1" type="revolute">
      <parent link="L2L1_J2"/>
      <child link="L1"/>
      <origin rpy="0 0 0" xyz="0 0 0"/>
      <axis xyz="0 1 0"/>
      <limit effort="0" lower="-0.1" upper="0.1" velocity="1.0"/>
   </joint>
   <joint name="L1Thorax_J1" type="revolute">
      <parent link="L1"/>
      <child link="L1Thorax_J1"/>
      <origin rpy="0 0 0" xyz="-0.011333 0 0.029278"/>
      <axis xyz="1 0 0"/>
      <limit effort="0" lower="-0.2" upper="0.2" velocity="1.0"/>
   </joint>
   <joint name="L1Thorax_J2" type="revolute">
      <parent link="L1Thorax_J1"/>
      <child link="L1Thorax_J2"/>
      <origin rpy="0 0 0" xyz="0 0 0"/>
      <axis xyz="0 0 1"/>
      <limit effort="0" lower="-1.5" upper="1.5" velocity="1.0"/>
   </joint>
   <joint name="Thorax" type="revolute">
      <parent link="L1Thorax_J2"/>
      <child link="Thorax"/>
      <origin rpy="0 0 0" xyz="0 0 0"/>
      <axis xyz="0 1 0"/>
      <limit effort="0" lower="-0.5" upper="0.6" velocity="1.0"/>
   </joint>
   <joint name="A_ThoraxSkull_J1" type="revolute"> <!-- A_ added for order while parsing with ROS -->
      <parent link="Thorax"/>
      <child link="ThoraxSkull_J1"/>
      <origin rpy="0 0 0" xyz="0.0037778 0 0.42122"/>
      <axis xyz="1 0 0"/>
      <limit effort="0" lower="-0.3" upper="0.3" velocity="1.0"/>
   </joint>
   <joint name="ThoraxSkull_J2" type="revolute">
      <parent link="ThoraxSkull_J1"/>
      <child link="ThoraxSkull_J2"/>
      <origin rpy="0 0 0" xyz="0 0 0"/>
      <axis xyz="0 0 1"/>
      <limit effort="0" lower="-1.4" upper="1.4" velocity="1.0"/>
   </joint>
   <joint name="Skull" type="revolute">
      <parent link="ThoraxSkull_J2"/>
      <child link="Skull"/>
      <origin rpy="0 0 0" xyz="0 0 0"/>
      <axis xyz="0 1 0"/>
      <limit effort="0" lower="-1.1" upper="0.4" velocity="1.0"/>
   </joint>
   <joint name="RHip_J1" type="revolute">
      <parent link="Pelvis"/>
      <child link="RHip_J1"/>
      <origin rpy="0 0 0" xyz="-0.0075556 -0.075556 -0.047222"/>
      <axis xyz="1 0 0"/>
      <limit effort="0" lower="-1" upper="0.3" velocity="1.0"/>
   </joint>
   <joint name="RHip_J2" type="revolute">
      <parent link="RHip_J1"/>
      <child link="RHip_J2"/>
      <origin rpy="0 0 0" xyz="0 0 0"/>
      <axis xyz="0 0 1"/>
      <limit effort="0" lower="-1.1" upper="0.8" velocity="1.0"/>
   </joint>
   <joint name="RThigh" type="revolute">
      <parent link="RHip_J2"/>
      <child link="RThigh"/>
      <origin rpy="0 0 0" xyz="0 0 0"/>
      <axis xyz="0 1 0"/>
      <limit effort="0" lower="-2.3" upper="0.6" velocity="1.0"/>
   </joint>
   <joint name="RShank" type="revolute">
      <parent link="RThigh"/>
      <child link="RShank"/>
      <origin rpy="0 0 0" xyz="-0.023611 -0.0094444 -0.42972"/>
      <axis xyz="0 1 0"/>
      <limit effort="0" lower="-0.05" upper="2.7" velocity="1.0"/>
   </joint>
   <joint name="RAnkle_J1" type="revolute">
      <parent link="RShank"/>
      <child link="RAnkle_J1"/>
      <origin rpy="0 0 0" xyz="0 0 -0.43444"/>
      <axis xyz="0 1 0"/>
      <limit effort="0" lower="-1.4" upper="1.2" velocity="1.0"/>
   </joint>
   <joint name="RFoot" type="revolute">
      <parent link="RAnkle_J1"/>
      <child link="RFoot"/>
      <origin rpy="0 0 0" xyz="0 0 0"/>
      <axis xyz="0 0 1"/>
      <limit effort="0" lower="-0.4" upper="0.4" velocity="1.0"/>
   </joint>
   <joint name="RFootToe" type="revolute">
      <parent link="RFoot"/>
      <child link="RFootToe"/>
      <origin rpy="0 0 0" xyz="0.1162 -0.0175 -0.0583"/>
      <axis xyz="0 1 0"/>
      <limit effort="0" lower="-0.5" upper="0.5" velocity="1.0"/>
   </joint>
  <joint name="RFootSphere" type="fixed">
      <parent link="RFootToe"/>
      <child link="RFootSphere"/>
      <origin rpy="0 0 0" xyz="0.0147 0 -0.0147"/>
   </joint>
   <joint name="LHip_J1" type="revolute">
      <parent link="Pelvis"/>
      <child link="LHip_J1"/>
      <origin rpy="0 0 0" xyz="-0.0075556 0.075556 -0.047222"/>
      <axis xyz="1 0 0"/>
      <limit effort="0" lower="-0.3" upper="1" velocity="1.0"/>
   </joint>
   <joint name="LHip_J2" type="revolute">
      <parent link="LHip_J1"/>
      <child link="LHip_J2"/>
      <origin rpy="0 0 0" xyz="0 0 0"/>
      <axis xyz="0 0 1"/>
      <limit effort="0" lower="-0.8" upper="1.1" velocity="1.0"/>
   </joint>
   <joint name="LThigh" type="revolute">
      <parent link="LHip_J2"/>
      <child link="LThigh"/>
      <origin rpy="0 0 0" xyz="0 0 0"/>
      <axis xyz="0 1 0"/>
      <limit effort="0" lower="-2.3" upper="0.6" velocity="1.0"/>
   </joint>
   <joint name="LShank" type="revolute">
      <parent link="LThigh"/>
      <child link="LShank"/>
      <origin rpy="0 0 0" xyz="-0.023611 0.0094444 -0.42972"/>
      <axis xyz="0 1 0"/>
      <limit effort="0" lower="-0.05" upper="2.7" velocity="1.0"/>
   </joint>
   <joint name="LAnkle_J1" type="revolute">
      <parent link="LShank"/>
      <child link="LAnkle_J1"/>
      <origin rpy="0 0 0" xyz="0 0 -0.43444"/>
      <axis xyz="0 1 0"/>
      <limit effort="0" lower="-1.4" upper="1.2" velocity="1.0"/>
   </joint>
   <joint name="LFoot" type="revolute">
      <parent link="LAnkle_J1"/>
      <child link="LFoot"/>
      <origin rpy="0 0 0" xyz="0 0 0"/>
      <axis xyz="0 0 1"/>
      <limit effort="0" lower="-0.4" upper="0.4" velocity="1.0"/>
   </joint>
   <joint name="LFootToe" type="revolute">
      <parent link="LFoot"/>
      <child link="LFootToe"/>
      <origin rpy="0 0 0" xyz="0.1114 0.0168 -0.0571"/>
      <axis xyz="0 1 0"/>
      <limit effort="0" lower="-0.5" upper="0.5" velocity="1.0"/>
   </joint>
  <joint name="LFootSphere" type="fixed">
      <parent link="LFootToe"/>
      <child link="LFootSphere"/>
      <origin rpy="0 0 0" xyz="0.0195 0.0044 -0.0159"/>
   </joint>
   <joint name="RShoulder_J1" type="revolute">
      <parent link="Thorax"/>
      <child link="RShoulder_J1"/>
      <origin rpy="0 0 0" xyz="-0.0026444 -0.18218 0.24452"/>
      <axis xyz="1 0 0"/>
      <limit effort="0" lower="-2.1" upper="0.4" velocity="1.0"/>
   </joint>
   <joint name="RShoulder_J2" type="revolute">
      <parent link="RShoulder_J1"/>
      <child link="RShoulder_J2"/>
      <origin rpy="0 0 0" xyz="0 0 0"/>
      <axis xyz="0 0 1"/>
      <limit effort="0" lower="-1.1" upper="2" velocity="1.0"/>
   </joint>
   <joint name="RHumerus" type="revolute">
      <parent link="RShoulder_J2"/>
      <child link="RHumerus"/>
      <origin rpy="0 0 0" xyz="0 0 0"/>
      <axis xyz="0 1 0"/>
      <limit effort="0" lower="-2.7" upper="1.7" velocity="1.0"/>
   </joint>
   <joint name="RElbow_J1" type="revolute">
      <parent link="RHumerus"/>
      <child link="RElbow_J1"/>
      <origin rpy="0 0 0" xyz="0 0 -0.3162"/>
      <axis xyz="0 1 0"/>
      <limit effort="0" lower="-2.7" upper="0.05" velocity="1.0"/>
   </joint>
   <joint name="RForearm" type="revolute">
      <parent link="RElbow_J1"/>
      <child link="RForearm"/>
      <origin rpy="0 0 0" xyz="0 0 0"/>
      <axis xyz="0 0 1"/>
      <limit effort="0" lower="-0.4" upper="3.2" velocity="1.0"/>
   </joint>
   <joint name="RWrist_J1" type="revolute">
      <parent link="RForearm"/>
      <child link="RWrist_J1"/>
      <origin rpy="0 0 0" xyz="0 0 -0.2482"/>
      <axis xyz="0 1 0"/>
      <limit effort="0" lower="-1.4" upper="1.2" velocity="1.0"/>
   </joint>
   <joint name="RHand" type="revolute">
      <parent link="RWrist_J1"/>
      <child link="RHand"/>
      <origin rpy="0 0 0" xyz="0 0 0"/>
      <axis xyz="1 0 0"/>
      <limit effort="0" lower="-0.3" upper="0.4" velocity="1.0"/>
   </joint>
  <joint name="RHandSphere" type="fixed">
      <parent link="RHand"/>
      <child link="RHandSphere"/>
      <origin rpy="0 0 0" xyz="0.035 0 -0.067"/>
   </joint>
   <joint name="LShoulder_J1" type="revolute">
      <parent link="Thorax"/>
      <child link="LShoulder_J1"/>
      <origin rpy="0 0 0" xyz="-0.0026444 0.18218 0.24452"/>
      <axis xyz="1 0 0"/>
      <limit effort="0" lower="-0.4" upper="2.1" velocity="1.0"/>
   </joint>
   <joint name="LShoulder_J2" type="revolute">
      <parent link="LShoulder_J1"/>
      <child link="LShoulder_J2"/>
      <origin rpy="0 0 0" xyz="0 0 0"/>
      <axis xyz="0 0 1"/>
      <limit effort="0" lower="-2" upper="1.1" velocity="1.0"/>
   </joint>
   <joint name="LHumerus" type="revolute">
      <parent link="LShoulder_J2"/>
      <child link="LHumerus"/>
      <origin rpy="0 0 0" xyz="0 0 0"/>
      <axis xyz="0 1 0"/>
      <limit effort="0" lower="-2.8" upper="1.7" velocity="1.0"/>
   </joint>
   <joint name="LElbow_J1" type="revolute">
      <parent link="LHumerus"/>
      <child link="LElbow_J1"/>
      <origin rpy="0 0 0" xyz="0 0 -0.3162"/>
      <axis xyz="0 1 0"/>
      <limit effort="0" lower="-2.7" upper="0.05" velocity="1.0"/>
   </joint>
   <joint name="LForearm" type="revolute">
      <parent link="LElbow_J1"/>
      <child link="LForearm"/>
      <origin rpy="0 0 0" xyz="0 0 0"/>
      <axis xyz="0 0 1"/>
      <limit effort="0" lower="-3.2" upper="0.4" velocity="1.0"/>
   </joint>
   <joint name="LWrist_J1" type="revolute">
      <parent link="LForearm"/>
      <child link="LWrist_J1"/>
      <origin rpy="0 0 0" xyz="0 0 -0.2482"/>
      <axis xyz="0 1 0"/>
      <limit effort="0" lower="-1.4" upper="1.2" velocity="1.0"/>
   </joint>
   <joint name="LHand" type="revolute">
      <parent link="LWrist_J1"/>
      <child link="LHand"/>
      <origin rpy="0 0 0" xyz="0 0 0"/>
      <axis xyz="1 0 0"/>
      <limit effort="0" lower="-0.4" upper="0.3" velocity="1.0"/>
   </joint>
  <joint name="LHandSphere" type="fixed">
      <parent link="LHand"/>
      <child link="LHandSphere"/>
      <origin rpy="0 0 0" xyz="0.035 0 -0.067"/>
   </joint>
</robot>
