<?xml version="1.0"?>
<robot name="frog">

  <material name="Blue"> <!-- for spheres -->
    <color rgba="0 0 1 0.5"/>
  </material>
  <material name="White">
    <color rgba="1 1 1 1"/>
  </material>
  <material name="Gray"> <!-- for ROMs -->
    <color rgba="0.6 0.6 0.6 0.4"/>
  </material>
  <material name="Green">
    <color rgba="0 1 0 1"/>
  </material>

  <link name="base_link"/>
  <joint name="base_link_J" type="fixed">
      <parent link="base_link"/>
      <child link="Torso"/>
      <origin rpy="0 0 0" xyz="0 0 0"/>
   </joint>

  <link name="virtualTorso"/> <!-- for Blender Armature export -->
  <joint name="virtualTorso" type="fixed">
      <parent link="base_link"/>
      <child link="virtualTorso"/>
      <origin rpy="0 0 0" xyz="0 0 0"/>
  </joint>

  <link name="Torso">
      <inertial>
         <origin rpy="0 0 0" xyz="0 0 0"/>
         <mass value="1"/>
         <inertia ixx="0" ixy="0" ixz="0" iyy="0" iyz="0" izz="0"/>
      </inertial>
      <visual>
         <origin xyz="0 0 0" rpy="0 0 0"/>
         <geometry>
            <mesh filename="package://hpp-rbprm-corba/meshes/frog/Torso.stl"/>
         </geometry>
		 <material name="Green"/>
      </visual>
      <collision>
         <origin xyz="0 0 0" rpy="0 0 0"/>
         <geometry>
            <mesh filename="package://hpp-rbprm-corba/meshes/frog/Torso.stl"/>
         </geometry>
      </collision>
   </link>

   <!--<joint name="torso_rom_joint" type="fixed">
      <parent link="Torso"/>
      <child link="torso_rom"/>
      <origin rpy="0 0 0" xyz="0 0 0"/>
   </joint>

  <link name="torso_rom">
      <visual>
         <origin xyz="0 0 0" rpy="0 0 0"/>
         <geometry>
            <mesh filename="package://hpp-rbprm-corba/meshes/frog/lfoot_rom.stl"/>
         </geometry>
         <material name="Gray"/>
      </visual>
   </link>-->

   <link name="Head_rx"/>
   <link name="Head_ry"/>
   <link name="Head">
      <inertial>
         <origin rpy="0 0 0" xyz="0 0 0"/>
         <mass value="0"/>
         <inertia ixx="0" ixy="0" ixz="0" iyy="0" iyz="0" izz="0"/>
      </inertial>
      <visual>
         <origin xyz="0 0 0" rpy="0 0 0"/>
         <geometry>
            <mesh filename="package://hpp-rbprm-corba/meshes/frog/Head.stl"/>
         </geometry>
		 <material name="Green"/>
      </visual>
      <collision>
         <origin xyz="0 0 0" rpy="0 0 0"/>
         <geometry>
            <mesh filename="package://hpp-rbprm-corba/meshes/frog/Head.stl"/>
         </geometry>
      </collision>
   </link>

  <!--<joint name="head_rom_joint" type="fixed">
      <parent link="Head"/>
      <child link="head_rom"/>
      <origin rpy="0 0 0" xyz="0 0 0"/>
   </joint>

  <link name="head_rom">
      <visual>
         <origin xyz="0 0 0" rpy="0 0 0"/>
         <geometry>
            <mesh filename="package://hpp-rbprm-corba/meshes/frog/rhand_rom.stl"/>
         </geometry>
         <material name="Gray"/>
      </visual>
   </link>-->
  
   <!-- L = left, R = right-->
   <link name="LThigh_rx"/>
   <link name="LThigh_ry"/>
   <link name="LThigh">
      <inertial>
         <origin rpy="0 0 0" xyz="0 0 0"/>
         <mass value="1"/>
         <inertia ixx="0.0071027" ixy="-0.00059867" ixz="-2.9564e-05" iyy="0.0046194" iyz="6.6519e-05" izz="0.0080488"/>
      </inertial>
      <visual>
         <origin xyz="0 0 0" rpy="0 0 0"/>
         <geometry>
            <mesh filename="package://hpp-rbprm-corba/meshes/frog/LThigh.stl"/>
         </geometry>
         <material name="Green"/>
      </visual>
      <collision>
         <origin xyz="0 0 0" rpy="0 0 0"/>
         <geometry>
            <mesh filename="package://hpp-rbprm-corba/meshes/frog/LThigh.stl"/>
         </geometry>
      </collision>
   </link>
   
   <link name="LShank_rx"/>
   <link name="LShank_ry"/>
   <link name="LShank">
      <inertial>
         <origin rpy="0 0 0" xyz="0 0 0"/>
         <mass value="1"/>
         <inertia ixx="0.0071027" ixy="-0.00059867" ixz="-2.9564e-05" iyy="0.0046194" iyz="6.6519e-05" izz="0.0080488"/>
      </inertial>
      <visual>
         <origin xyz="0 0 0" rpy="0 0 0"/>
         <geometry>
            <mesh filename="package://hpp-rbprm-corba/meshes/frog/LShank.stl"/>
         </geometry>
         <material name="Green"/>
      </visual>
      <collision>
         <origin xyz="0 0 0" rpy="0 0 0"/>
         <geometry>
            <mesh filename="package://hpp-rbprm-corba/meshes/frog/LShank.stl"/>
         </geometry>
      </collision>
   </link>
   
   <link name="LFoot_rx"/>
   <link name="LFoot_ry"/>
   <link name="LFoot">
      <inertial>
         <origin rpy="0 0 0" xyz="0 0 0"/>
         <mass value="1"/>
         <inertia ixx="0.0071027" ixy="-0.00059867" ixz="-2.9564e-05" iyy="0.0046194" iyz="6.6519e-05" izz="0.0080488"/>
      </inertial>
      <visual>
         <origin xyz="0 0 0" rpy="0 0 0"/>
         <geometry>
            <mesh filename="package://hpp-rbprm-corba/meshes/frog/LFoot.stl"/>
         </geometry>
         <material name="Green"/>
      </visual>
      <collision>
         <origin xyz="0 0 0" rpy="0 0 0"/>
         <geometry>
            <mesh filename="package://hpp-rbprm-corba/meshes/frog/LFoot.stl"/>
         </geometry>
      </collision>
   </link>
   
   <link name="FrogLFootSphere">
      <visual>
         <origin xyz="0 0 0" rpy="0 0 0"/>
         <geometry>
            <sphere radius="0.005"/>
         </geometry>
         <material name="Blue"/>
      </visual>
   </link>
   
   <link name="RThigh_rx"/>
   <link name="RThigh_ry"/>
   <link name="RThigh">
      <inertial>
         <origin rpy="0 0 0" xyz="0 0 0"/>
         <mass value="1"/>
         <inertia ixx="0.0071027" ixy="-0.00059867" ixz="-2.9564e-05" iyy="0.0046194" iyz="6.6519e-05" izz="0.0080488"/>
      </inertial>
      <visual>
         <origin xyz="0 0 0" rpy="0 0 0"/>
         <geometry>
            <mesh filename="package://hpp-rbprm-corba/meshes/frog/RThigh.stl"/>
         </geometry>
         <material name="Green"/>
      </visual>
      <collision>
         <origin xyz="0 0 0" rpy="0 0 0"/>
         <geometry>
            <mesh filename="package://hpp-rbprm-corba/meshes/frog/RThigh.stl"/>
         </geometry>
      </collision>
   </link>
   
   <link name="RShank_rx"/>
   <link name="RShank_ry"/>
   <link name="RShank">
      <inertial>
         <origin rpy="0 0 0" xyz="0 0 0"/>
         <mass value="1"/>
         <inertia ixx="0.0071027" ixy="-0.00059867" ixz="-2.9564e-05" iyy="0.0046194" iyz="6.6519e-05" izz="0.0080488"/>
      </inertial>
      <visual>
         <origin xyz="0 0 0" rpy="0 0 0"/>
         <geometry>
            <mesh filename="package://hpp-rbprm-corba/meshes/frog/RShank.stl"/>
         </geometry>
         <material name="Green"/>
      </visual>
      <collision>
         <origin xyz="0 0 0" rpy="0 0 0"/>
         <geometry>
            <mesh filename="package://hpp-rbprm-corba/meshes/frog/RShank.stl"/>
         </geometry>
      </collision>
   </link>
   
   <link name="RFoot_rx"/>
   <link name="RFoot_ry"/>
   <link name="RFoot">
      <inertial>
         <origin rpy="0 0 0" xyz="0 0 0"/>
         <mass value="1"/>
         <inertia ixx="0.0071027" ixy="-0.00059867" ixz="-2.9564e-05" iyy="0.0046194" iyz="6.6519e-05" izz="0.0080488"/>
      </inertial>
      <visual>
         <origin xyz="0 0 0" rpy="0 0 0"/>
         <geometry>
            <mesh filename="package://hpp-rbprm-corba/meshes/frog/RFoot.stl"/>
         </geometry>
         <material name="Green"/>
      </visual>
      <collision>
         <origin xyz="0 0 0" rpy="0 0 0"/>
         <geometry>
            <mesh filename="package://hpp-rbprm-corba/meshes/frog/RFoot.stl"/>
         </geometry>
      </collision>
   </link>
   
   <link name="FrogRFootSphere">
      <visual>
         <origin xyz="0 0 0" rpy="0 0 0"/>
         <geometry>
            <sphere radius="0.005"/>
         </geometry>
         <material name="Blue"/>
      </visual>
   </link>
  
   <link name="LHumerus_rx"/>
   <link name="LHumerus_ry"/>
   <link name="LHumerus">
      <inertial>
         <origin rpy="0 0 0" xyz="0 0 0"/>
         <mass value="1"/>
         <inertia ixx="0.0071027" ixy="-0.00059867" ixz="-2.9564e-05" iyy="0.0046194" iyz="6.6519e-05" izz="0.0080488"/>
      </inertial>
      <visual>
         <origin xyz="0 0 0" rpy="0 0 0"/>
         <geometry>
            <mesh filename="package://hpp-rbprm-corba/meshes/frog/LHumerus.stl"/>
         </geometry>
         <material name="Green"/>
      </visual>
      <collision>
         <origin xyz="0 0 0" rpy="0 0 0"/>
         <geometry>
            <mesh filename="package://hpp-rbprm-corba/meshes/frog/LHumerus.stl"/>
         </geometry>
      </collision>
   </link>
   
   <link name="LForearm_rx"/>
   <link name="LForearm_ry"/>
   <link name="LForearm">
      <inertial>
         <origin rpy="0 0 0" xyz="0 0 0"/>
         <mass value="1"/>
         <inertia ixx="0.0071027" ixy="-0.00059867" ixz="-2.9564e-05" iyy="0.0046194" iyz="6.6519e-05" izz="0.0080488"/>
      </inertial>
      <visual>
         <origin xyz="0 0 0" rpy="0 0 0"/>
         <geometry>
            <mesh filename="package://hpp-rbprm-corba/meshes/frog/LForearm.stl"/>
         </geometry>
         <material name="Green"/>
      </visual>
      <collision>
         <origin xyz="0 0 0" rpy="0 0 0"/>
         <geometry>
            <mesh filename="package://hpp-rbprm-corba/meshes/frog/LForearm.stl"/>
         </geometry>
      </collision>
   </link>

   <link name="LHand_rx"/>
   <link name="LHand_ry"/>
   <link name="LHand">
      <inertial>
         <origin rpy="0 0 0" xyz="0 0 0"/>
         <mass value="1"/>
         <inertia ixx="0.0071027" ixy="-0.00059867" ixz="-2.9564e-05" iyy="0.0046194" iyz="6.6519e-05" izz="0.0080488"/>
      </inertial>
      <visual>
         <origin xyz="0 0 0" rpy="0 0 0"/>
         <geometry>
            <mesh filename="package://hpp-rbprm-corba/meshes/frog/LHand.stl"/>
         </geometry>
         <material name="Green"/>
      </visual>
      <collision>
         <origin xyz="0 0 0" rpy="0 0 0"/>
         <geometry>
            <mesh filename="package://hpp-rbprm-corba/meshes/frog/LHand.stl"/>
         </geometry>
      </collision>
   </link>
   
   <link name="FrogLHandSphere">
      <visual>
         <origin xyz="0 0 0" rpy="0 0 0"/>
         <geometry>
            <sphere radius="0.005"/>
         </geometry>
         <material name="Blue"/>
      </visual>
   </link>

   <link name="RHumerus_rx"/>
   <link name="RHumerus_ry"/>
   <link name="RHumerus">
      <inertial>
         <origin rpy="0 0 0" xyz="0 0 0"/>
         <mass value="1"/>
         <inertia ixx="0.0071027" ixy="-0.00059867" ixz="-2.9564e-05" iyy="0.0046194" iyz="6.6519e-05" izz="0.0080488"/>
      </inertial>
      <visual>
         <origin xyz="0 0 0" rpy="0 0 0"/>
         <geometry>
            <mesh filename="package://hpp-rbprm-corba/meshes/frog/RHumerus.stl"/>
         </geometry>
         <material name="Green"/>
      </visual>
      <collision>
         <origin xyz="0 0 0" rpy="0 0 0"/>
         <geometry>
            <mesh filename="package://hpp-rbprm-corba/meshes/frog/RHumerus.stl"/>
         </geometry>
      </collision>
   </link>
   
   <link name="RForearm_rx"/>
   <link name="RForearm_ry"/>
   <link name="RForearm">
      <inertial>
         <origin rpy="0 0 0" xyz="0 0 0"/>
         <mass value="1"/>
         <inertia ixx="0.0071027" ixy="-0.00059867" ixz="-2.9564e-05" iyy="0.0046194" iyz="6.6519e-05" izz="0.0080488"/>
      </inertial>
      <visual>
         <origin xyz="0 0 0" rpy="0 0 0"/>
         <geometry>
            <mesh filename="package://hpp-rbprm-corba/meshes/frog/RForearm.stl"/>
         </geometry>
         <material name="Green"/>
      </visual>
      <collision>
         <origin xyz="0 0 0" rpy="0 0 0"/>
         <geometry>
            <mesh filename="package://hpp-rbprm-corba/meshes/frog/RForearm.stl"/>
         </geometry>
      </collision>
   </link>

   <link name="RHand_rx"/>
   <link name="RHand_ry"/>
   <link name="RHand">
      <inertial>
         <origin rpy="0 0 0" xyz="0 0 0"/>
         <mass value="1"/>
         <inertia ixx="0.0071027" ixy="-0.00059867" ixz="-2.9564e-05" iyy="0.0046194" iyz="6.6519e-05" izz="0.0080488"/>
      </inertial>
      <visual>
         <origin xyz="0 0 0" rpy="0 0 0"/>
         <geometry>
            <mesh filename="package://hpp-rbprm-corba/meshes/frog/RHand.stl"/>
         </geometry>
         <material name="Green"/>
      </visual>
      <collision>
         <origin xyz="0 0 0" rpy="0 0 0"/>
         <geometry>
            <mesh filename="package://hpp-rbprm-corba/meshes/frog/RHand.stl"/>
         </geometry>
      </collision>
   </link>
   
   <link name="FrogRHandSphere">
      <visual>
         <origin xyz="0 0 0" rpy="0 0 0"/>
         <geometry>
            <sphere radius="0.005"/>
         </geometry>
         <material name="Blue"/>
      </visual>
   </link>
   

   <!-- JOINTS -->
  <joint name="Head_rx" type="revolute">
      <parent link="Torso"/>
      <child link="Head_rx"/>
      <origin rpy="0 0 0" xyz="0.0296 0.0000897 0.0205"/>
      <axis xyz="1 0 0"/>
      <limit effort="0" lower="-0.2" upper="0.2" velocity="1.0"/>
   </joint>
   <joint name="Head_ry" type="revolute">
      <parent link="Head_rx"/>
      <child link="Head_ry"/>
      <origin rpy="0 0 0" xyz="0 0 0"/>
      <axis xyz="0 1 0"/>
      <limit effort="0" lower="-0.2" upper="0.2" velocity="1.0"/>
   </joint>
   <joint name="Head_rz" type="revolute">
      <parent link="Head_ry"/>
      <child link="Head"/>
      <origin rpy="0 0 0" xyz="0 0 0"/>
      <axis xyz="0 0 1"/>
      <limit effort="0" lower="-0.2" upper="0.2" velocity="1.0"/>
   </joint>
   
   <!-- left side -->
  <joint name="LThigh_rx" type="revolute">
      <parent link="Torso"/>
      <child link="LThigh_rx"/>
      <origin rpy="0 0 0" xyz="-0.0802 0.0196 -0.0173"/>
      <axis xyz="1 0 0"/>
      <limit effort="0" lower="-0.7" upper="0.7" velocity="1.0"/>
   </joint>
   <joint name="LThigh_ry" type="revolute">
      <parent link="LThigh_rx"/>
      <child link="LThigh_ry"/>
      <origin rpy="0 0 0" xyz="0 0 0"/>
      <axis xyz="0 1 0"/>
      <limit effort="0" lower="-0.9" upper="0.3" velocity="1.0"/>
   </joint>
   <joint name="LThigh_rz" type="revolute">
      <parent link="LThigh_ry"/>
      <child link="LThigh"/>
      <origin rpy="0 0 0" xyz="0 0 0"/>
      <axis xyz="0 0 1"/>
      <limit effort="0" lower="-1.3" upper="0.2" velocity="1.0"/>
   </joint>
  <joint name="LShank_rx" type="revolute">
      <parent link="LThigh"/>
      <child link="LShank_rx"/>
      <origin rpy="0 0 0" xyz="-0.0221 0.0676 -0.0232"/>
      <axis xyz="1 0 0"/>
      <limit effort="0" lower="-0.1" upper="0.1" velocity="1.0"/>
   </joint>
   <joint name="LShank_ry" type="revolute">
      <parent link="LShank_rx"/>
      <child link="LShank_ry"/>
      <origin rpy="0 0 0" xyz="0 0 0"/>
      <axis xyz="0 1 0"/>
      <limit effort="0" lower="-0.3" upper="0.5" velocity="1.0"/>
   </joint>
   <joint name="LShank_rz" type="revolute">
      <parent link="LShank_ry"/>
      <child link="LShank"/>
      <origin rpy="0 0 0" xyz="0 0 0"/>
      <axis xyz="0 0 1"/>
      <limit effort="0" lower="-0.8" upper="1.1" velocity="1.0"/>
   </joint>
  <joint name="LFoot_rx" type="revolute">
      <parent link="LShank"/>
      <child link="LFoot_rx"/>
      <origin rpy="0 0 0" xyz="-0.1130 -0.0525 0.0027"/>
      <axis xyz="1 0 0"/>
      <limit effort="0" lower="-0.4" upper="0.4" velocity="1.0"/>
   </joint>
   <joint name="LFoot_ry" type="revolute">
      <parent link="LFoot_rx"/>
      <child link="LFoot_ry"/>
      <origin rpy="0 0 0" xyz="0 0 0"/>
      <axis xyz="0 1 0"/>
      <limit effort="0" lower="-0.2" upper="0.2" velocity="1.0"/>
   </joint>
   <joint name="LFoot_rz" type="revolute">
      <parent link="LFoot_ry"/>
      <child link="LFoot"/>
      <origin rpy="0 0 0" xyz="0 0 0"/>
      <axis xyz="0 0 1"/>
      <limit effort="0" lower="-1.3" upper="0.8" velocity="1.0"/>
   </joint>
   <joint name="FrogLFootSphere" type="fixed">
      <parent link="LFoot"/>
      <child link="FrogLFootSphere"/>
      <origin rpy="0 0 0" xyz="-0.0436 0.0776 -0.032"/>
   </joint>
   
  <joint name="LHumerus_rx" type="revolute">
      <parent link="Head"/>
      <child link="LHumerus_rx"/>
      <origin rpy="0 0 0" xyz="0.0313 0.0379 -0.0261"/>
      <axis xyz="1 0 0"/>
      <limit effort="0" lower="-0.7" upper="0.7" velocity="1.0"/>
   </joint>
   <joint name="LHumerus_ry" type="revolute">
      <parent link="LHumerus_rx"/>
      <child link="LHumerus_ry"/>
      <origin rpy="0 0 0" xyz="0 0 0"/>
      <axis xyz="0 1 0"/>
      <limit effort="0" lower="-0.7" upper="0.7" velocity="1.0"/>
   </joint>
   <joint name="LHumerus_rz" type="revolute">
      <parent link="LHumerus_ry"/>
      <child link="LHumerus"/>
      <origin rpy="0 0 0" xyz="0 0 0"/>
      <axis xyz="0 0 1"/>
      <limit effort="0" lower="-0.4" upper="0.4" velocity="1.0"/>
   </joint>
  <joint name="LForearm_rx" type="revolute">
      <parent link="LHumerus"/>
      <child link="LForearm_rx"/>
      <origin rpy="0 0 0" xyz="0.0049 0.0258 -0.0184"/>
      <axis xyz="1 0 0"/>
      <limit effort="0" lower="-0.6" upper="0.6" velocity="1.0"/>
   </joint>
   <joint name="LForearm_ry" type="revolute">
      <parent link="LForearm_rx"/>
      <child link="LForearm_ry"/>
      <origin rpy="0 0 0" xyz="0 0 0"/>
      <axis xyz="0 1 0"/>
      <limit effort="0" lower="-0.6" upper="0.6" velocity="1.0"/>
   </joint>
   <joint name="LForearm_rz" type="revolute">
      <parent link="LForearm_ry"/>
      <child link="LForearm"/>
      <origin rpy="0 0 0" xyz="0 0 0"/>
      <axis xyz="0 0 1"/>
      <limit effort="0" lower="-0.5" upper="0.5" velocity="1.0"/>
   </joint>
  <joint name="LHand_rx" type="revolute">
      <parent link="LForearm"/>
      <child link="LHand_rx"/>
      <origin rpy="0 0 0" xyz="0.0314 -0.0127 -0.0189"/>
      <axis xyz="1 0 0"/>
      <limit effort="0" lower="-0.45" upper="0.45" velocity="1.0"/>
   </joint>
   <joint name="LHand_ry" type="revolute">
      <parent link="LHand_rx"/>
      <child link="LHand_ry"/>
      <origin rpy="0 0 0" xyz="0 0 0"/>
      <axis xyz="0 1 0"/>
      <limit effort="0" lower="-0.3" upper="0.3" velocity="1.0"/>
   </joint>
   <joint name="LHand_rz" type="revolute">
      <parent link="LHand_ry"/>
      <child link="LHand"/>
      <origin rpy="0 0 0" xyz="0 0 0"/>
      <axis xyz="0 0 1"/>
      <limit effort="0" lower="-0.3" upper="0.3" velocity="1.0"/>
   </joint>
   <joint name="FrogLHandSphere" type="fixed">
      <parent link="LHand"/>
      <child link="FrogLHandSphere"/>
      <origin rpy="0 -0.1 0" xyz="0.0184 -0.0116 -0.0103"/>
   </joint>
   
   <!-- right side -->
  <joint name="RThigh_rx" type="revolute">
      <parent link="Torso"/>
      <child link="RThigh_rx"/>
      <origin rpy="0 0 0" xyz="-0.0806 -0.0223 -0.0182"/>
      <axis xyz="1 0 0"/>
      <limit effort="0" lower="-0.7" upper="0.7" velocity="1.0"/>
   </joint>
   <joint name="RThigh_ry" type="revolute">
      <parent link="RThigh_rx"/>
      <child link="RThigh_ry"/>
      <origin rpy="0 0 0" xyz="0 0 0"/>
      <axis xyz="0 1 0"/>
      <limit effort="0" lower="-0.9" upper="0.3" velocity="1.0"/>
   </joint>
   <joint name="RThigh_rz" type="revolute">
      <parent link="RThigh_ry"/>
      <child link="RThigh"/>
      <origin rpy="0 0 0" xyz="0 0 0"/>
      <axis xyz="0 0 1"/>
      <limit effort="0" lower="-0.2" upper="1.3" velocity="1.0"/>
   </joint>
  <joint name="RShank_rx" type="revolute">
      <parent link="RThigh"/>
      <child link="RShank_rx"/>
      <origin rpy="0 0 0" xyz="-0.0275 -0.0739 -0.0259"/>
      <axis xyz="1 0 0"/>
      <limit effort="0" lower="-0.1" upper="0.1" velocity="1.0"/>
   </joint>
   <joint name="RShank_ry" type="revolute">
      <parent link="RShank_rx"/>
      <child link="RShank_ry"/>
      <origin rpy="0 0 0" xyz="0 0 0"/>
      <axis xyz="0 1 0"/>
      <limit effort="0" lower="-0.3" upper="0.5" velocity="1.0"/>
   </joint>
   <joint name="RShank_rz" type="revolute">
      <parent link="RShank_ry"/>
      <child link="RShank"/>
      <origin rpy="0 0 0" xyz="0 0 0"/>
      <axis xyz="0 0 1"/>
      <limit effort="0" lower="-1.1" upper="0.8" velocity="1.0"/>
   </joint>
  <joint name="RFoot_rx" type="revolute">
      <parent link="RShank"/>
      <child link="RFoot_rx"/>
      <origin rpy="0 0 0" xyz="-0.1107 0.0556 0.0042"/>
      <axis xyz="1 0 0"/>
      <limit effort="0" lower="-0.4" upper="0.4" velocity="1.0"/>
   </joint>
   <joint name="RFoot_ry" type="revolute">
      <parent link="RFoot_rx"/>
      <child link="RFoot_ry"/>
      <origin rpy="0 0 0" xyz="0 0 0"/>
      <axis xyz="0 1 0"/>
      <limit effort="0" lower="-0.2" upper="0.2" velocity="1.0"/>
   </joint>
   <joint name="RFoot_rz" type="revolute">
      <parent link="RFoot_ry"/>
      <child link="RFoot"/>
      <origin rpy="0 0 0" xyz="0 0 0"/>
      <axis xyz="0 0 1"/>
      <limit effort="0" lower="-0.8" upper="1.3" velocity="1.0"/>
   </joint>
   <joint name="FrogRFootSphere" type="fixed">
      <parent link="RFoot"/>
      <child link="FrogRFootSphere"/>
      <origin rpy="0 0 0" xyz="-0.0461 -0.0853 -0.032"/>
   </joint>
   
  <joint name="RHumerus_rx" type="revolute">
      <parent link="Head"/>
      <child link="RHumerus_rx"/>
      <origin rpy="0 0 0" xyz="0.0323 -0.0394 -0.0279"/>
      <axis xyz="1 0 0"/>
      <limit effort="0" lower="-0.8" upper="0.8" velocity="1.0"/>
   </joint>
   <joint name="RHumerus_ry" type="revolute">
      <parent link="RHumerus_rx"/>
      <child link="RHumerus_ry"/>
      <origin rpy="0 0 0" xyz="0 0 0"/>
      <axis xyz="0 1 0"/>
      <limit effort="0" lower="-0.8" upper="0.8" velocity="1.0"/>
   </joint>
   <joint name="RHumerus_rz" type="revolute">
      <parent link="RHumerus_ry"/>
      <child link="RHumerus"/>
      <origin rpy="0 0 0" xyz="0 0 0"/>
      <axis xyz="0 0 1"/>
      <limit effort="0" lower="-0.4" upper="0.4" velocity="1.0"/>
   </joint>
  <joint name="RForearm_rx" type="revolute">
      <parent link="RHumerus"/>
      <child link="RForearm_rx"/>
      <origin rpy="0 0 0" xyz="0.0050 -0.0245 -0.0171"/>
      <axis xyz="1 0 0"/>
      <limit effort="0" lower="-0.6" upper="0.6" velocity="1.0"/>
   </joint>
   <joint name="RForearm_ry" type="revolute">
      <parent link="RForearm_rx"/>
      <child link="RForearm_ry"/>
      <origin rpy="0 0 0" xyz="0 0 0"/>
      <axis xyz="0 1 0"/>
      <limit effort="0" lower="-0.6" upper="0.6" velocity="1.0"/>
   </joint>
   <joint name="RForearm_rz" type="revolute">
      <parent link="RForearm_ry"/>
      <child link="RForearm"/>
      <origin rpy="0 0 0" xyz="0 0 0"/>
      <axis xyz="0 0 1"/>
      <limit effort="0" lower="-0.5" upper="0.5" velocity="1.0"/>
   </joint>
  <joint name="RHand_rx" type="revolute">
      <parent link="RForearm"/>
      <child link="RHand_rx"/>
      <origin rpy="0 0 0" xyz="0.0318 0.0138 -0.0191"/>
      <axis xyz="1 0 0"/>
      <limit effort="0" lower="-0.45" upper="0.45" velocity="1.0"/>
   </joint>
   <joint name="RHand_ry" type="revolute">
      <parent link="RHand_rx"/>
      <child link="RHand_ry"/>
      <origin rpy="0 0 0" xyz="0 0 0"/>
      <axis xyz="0 1 0"/>
      <limit effort="0" lower="-0.3" upper="0.3" velocity="1.0"/>
   </joint>
   <joint name="RHand_rz" type="revolute">
      <parent link="RHand_ry"/>
      <child link="RHand"/>
      <origin rpy="0 0 0" xyz="0 0 0"/>
      <axis xyz="0 0 1"/>
      <limit effort="0" lower="-0.3" upper="0.3" velocity="1.0"/>
   </joint>
   <joint name="FrogRHandSphere" type="fixed">
      <parent link="RHand"/>
      <child link="FrogRHandSphere"/>
      <origin rpy="0 -0.1 0" xyz="0.0169 0.0106 -0.0096"/>
   </joint>
</robot>
